Workbook

Sheet 📊 Dashboard
A1: 📊 TABLEAU DE BORD — Portefeuille Brevets UM6P | S1: Tous | T1: Toutes | U1: Toutes | V1: Agriculture, biostimulants & protection végétale | W1: {=SUMPRODUCT(('📋 Inventaire Complet'!$C$3:$C$517=$V1)*(($B$5="Tous")+('📋 Inventaire Complet'!$B$3:$B$517=$B$5)>0)*(($E$5="Toutes")+(LEFT('📋 Inventaire Complet'!$J$3:$J$517,4)=$E$5&"")>0)*(($H$5="Toutes")+('📋 Inventaire Complet'!$F$3:$F$517=$H$5)>0)*(LEN('📋 Inventaire Complet'!$D$3:$D$517)>0)*(($K$5="Tous")+(ISNUMBER(SEARCH($K$5,'📋 Inventaire Complet'!$L$3:$L$517)))>0))} -> 0 | X1: =W1+ROW()/10000 -> 0.0001 | Y1: LAKSSIR, BOUZIDA, BENNANI | Z1: {=IF(Y1="",0,SUMPRODUCT(('📋 Inventaire Complet'!$E$3:$E$517=Y1)*((COUNTIF($B$6:$B$10,TRUE)=0)+ISNUMBER(IFERROR(MATCH('📋 Inventaire Complet'!$B$3:$B$517,IF($B$6:$B$10,$A$6:$A$10),0),""))>0)*((COUNTIF($D$6:$D$22,TRUE)=0)+ISNUMBER(IFERROR(MATCH(LEFT('📋 Inventaire Complet'!$J$3:$J$517,4),IF($D$6:$D$22,$C$6:$C$22&""),0),""))>0)*((COUNTIF($F$6:$F$20,TRUE)=0)+(ISNUMBER(IFERROR(MATCH('📋 Inventaire Complet'!$F$3:$F$517,IF($F$6:$F$19,$E$6:$E$19),0),""))+($F$20*ISNUMBER(MATCH('📋 Inventaire Complet'!$F$3:$F$517,{"D4R";"CEPH";"ISTI";"COLCOM";"HTMR"},0))))>0)*((COUNTIF($H$6:$H$10,TRUE)=0)+(($H$6*ISNUMBER(SEARCH($G$6,'📋 Inventaire Complet'!$L$3:$L$517)))+($H$7*ISNUMBER(SEARCH($G$7,'📋 Inventaire Complet'!$L$3:$L$517)))+($H$8*ISNUMBER(SEARCH($G$8,'📋 Inventaire Complet'!$L$3:$L$517)))+($H$9*ISNUMBER(SEARCH($G$9,'📋 Inventaire Complet'!$L$3:$L$517)))+($H$10*ISNUMBER(SEARCH($G$10,'📋 Inventaire Complet'!$L$3:$L$517))))>0)))} -> 1 | AA1: =IF(Y1="",0,Z1+ROW()/10000) -> 1.0001
S2: Environmental Tech & Digital Mining | T2: 2010 | U2: MAScIR | V2: Biotechnologies, diagnostic & molécules bioactives | W2: {=SUMPRODUCT(('📋 Inventaire Complet'!$C$3:$C$517=$V2)*(($B$5="Tous")+('📋 Inventaire Complet'!$B$3:$B$517=$B$5)>0)*(($E$5="Toutes")+(LEFT('📋 Inventaire Complet'!$J$3:$J$517,4)=$E$5&"")>0)*(($H$5="Toutes")+('📋 Inventaire Complet'!$F$3:$F$517=$H$5)>0)*(LEN('📋 Inventaire Complet'!$D$3:$D$517)>0)*(($K$5="Tous")+(ISNUMBER(SEARCH($K$5,'📋 Inventaire Complet'!$L$3:$L$517)))>0))} -> 0 | X2: =W2+ROW()/10000 -> 0.0002 | Y2: AMAR OUMKELTOUM; ZENNAYI YAHYA; BOURJA OMAR; BOURZEIX FRANCOIS | Z2: {=IF(Y2="",0,SUMPRODUCT(('📋 Inventaire Complet'!$E$3:$E$517=Y2)*((COUNTIF($B$6:$B$10,TRUE)=0)+ISNUMBER(IFERROR(MATCH('📋 Inventaire Complet'!$B$3:$B$517,IF($B$6:$B$10,$A$6:$A$10),0),""))>0)*((COUNTIF($D$6:$D$22,TRUE)=0)+ISNUMBER(IFERROR(MATCH(LEFT('📋 Inventaire Complet'!$J$3:$J$517,4),IF($D$6:$D$22,$C$6:$C$22&""),0),""))>0)*((COUNTIF($F$6:$F$20,TRUE)=0)+(ISNUMBER(IFERROR(MATCH('📋 Inventaire Complet'!$F$3:$F$517,IF($F$6:$F$19,$E$6:$E$19),0),""))+($F$20*ISNUMBER(MATCH('📋 Inventaire Complet'!$F$3:$F$517,{"D4R";"CEPH";"ISTI";"COLCOM";"HTMR"},0))))>0)*((COUNTIF($H$6:$H$10,TRUE)=0)+(($H$6*ISNUMBER(SEARCH($G$6,'📋 Inventaire Complet'!$L$3:$L$517)))+($H$7*ISNUMBER(SEARCH($G$7,'📋 Inventaire Complet'!$L$3:$L$517)))+($H$8*ISNUMBER(SEARCH($G$8,'📋 Inventaire Complet'!$L$3:$L$517)))+($H$9*ISNUMBER(SEARCH($G$9,'📋 Inventaire Complet'!$L$3:$L$517)))+($H$10*ISNUMBER(SEARCH($G$10,'📋 Inventaire Complet'!$L$3:$L$517))))>0)))} -> 1 | AA2: =IF(Y2="",0,Z2+ROW()/10000) -> 1.0002
S3: Mineral Processing & Strategic Synthesis | T3: 2011 | U3: OCP | CERPHOS (historique) | V3: Capteurs, spectroscopie & micro-ondes | W3: {=SUMPRODUCT(('📋 Inventaire Complet'!$C$3:$C$517=$V3)*(($B$5="Tous")+('📋 Inventaire Complet'!$B$3:$B$517=$B$5)>0)*(($E$5="Toutes")+(LEFT('📋 Inventaire Complet'!$J$3:$J$517,4)=$E$5&"")>0)*(($H$5="Toutes")+('📋 Inventaire Complet'!$F$3:$F$517=$H$5)>0)*(LEN('📋 Inventaire Complet'!$D$3:$D$517)>0)*(($K$5="Tous")+(ISNUMBER(SEARCH($K$5,'📋 Inventaire Complet'!$L$3:$L$517)))>0))} -> 0 | X3: =W3+ROW()/10000 -> 0.0003 | Y3: Yahya ZENNAYI; Hamd AIT ABDELALI; Soukayna BENAISSA; Jihad BOURASSI | Z3: {=IF(Y3="",0,SUMPRODUCT(('📋 Inventaire Complet'!$E$3:$E$517=Y3)*((COUNTIF($B$6:$B$10,TRUE)=0)+ISNUMBER(IFERROR(MATCH('📋 Inventaire Complet'!$B$3:$B$517,IF($B$6:$B$10,$A$6:$A$10),0),""))>0)*((COUNTIF($D$6:$D$22,TRUE)=0)+ISNUMBER(IFERROR(MATCH(LEFT('📋 Inventaire Complet'!$J$3:$J$517,4),IF($D$6:$D$22,$C$6:$C$22&""),0),""))>0)*((COUNTIF($F$6:$F$20,TRUE)=0)+(ISNUMBER(IFERROR(MATCH('📋 Inventaire Complet'!$F$3:$F$517,IF($F$6:$F$19,$E$6:$E$19),0),""))+($F$20*ISNUMBER(MATCH('📋 Inventaire Complet'!$F$3:$F$517,{"D4R";"CEPH";"ISTI";"COLCOM";"HTMR"},0))))>0)*((COUNTIF($H$6:$H$10,TRUE)=0)+(($H$6*ISNUMBER(SEARCH($G$6,'📋 Inventaire Complet'!$L$3:$L$517)))+($H$7*ISNUMBER(SEARCH($G$7,'📋 Inventaire Complet'!$L$3:$L$517)))+($H$8*ISNUMBER(SEARCH($G$8,'📋 Inventaire Complet'!$L$3:$L$517)))+($H$9*ISNUMBER(SEARCH($G$9,'📋 Inventaire Complet'!$L$3:$L$517)))+($H$10*ISNUMBER(SEARCH($G$10,'📋 Inventaire Complet'!$L$3:$L$517))))>0)))} -> 1 | AA3: =IF(Y3="",0,Z3+ROW()/10000) -> 1.0003
A4: 🔍 FILTRES INTERACTIFS — Cocher pour filtrer (multi-sélection). Aucune case cochée dans un filtre = toutes les valeurs. | S4: Circular Chemistry & Waste Valorization | T4: 2012 | U4: MSN | V4: Matériaux composites, polymères & revêtements | W4: {=SUMPRODUCT(('📋 Inventaire Complet'!$C$3:$C$517=$V4)*(($B$5="Tous")+('📋 Inventaire Complet'!$B$3:$B$517=$B$5)>0)*(($E$5="Toutes")+(LEFT('📋 Inventaire Complet'!$J$3:$J$517,4)=$E$5&"")>0)*(($H$5="Toutes")+('📋 Inventaire Complet'!$F$3:$F$517=$H$5)>0)*(LEN('📋 Inventaire Complet'!$D$3:$D$517)>0)*(($K$5="Tous")+(ISNUMBER(SEARCH($K$5,'📋 Inventaire Complet'!$L$3:$L$517)))>0))} -> 0 | X4: =W4+ROW()/10000 -> 0.0004 | Y4: BALOUIRI MOUNYR; EL HADI HICHAM; MOUMEN ABDELADIM | Z4: {=IF(Y4="",0,SUMPRODUCT(('📋 Inventaire Complet'!$E$3:$E$517=Y4)*((COUNTIF($B$6:$B$10,TRUE)=0)+ISNUMBER(IFERROR(MATCH('📋 Inventaire Complet'!$B$3:$B$517,IF($B$6:$B$10,$A$6:$A$10),0),""))>0)*((COUNTIF($D$6:$D$22,TRUE)=0)+ISNUMBER(IFERROR(MATCH(LEFT('📋 Inventaire Complet'!$J$3:$J$517,4),IF($D$6:$D$22,$C$6:$C$22&""),0),""))>0)*((COUNTIF($F$6:$F$20,TRUE)=0)+(ISNUMBER(IFERROR(MATCH('📋 Inventaire Complet'!$F$3:$F$517,IF($F$6:$F$19,$E$6:$E$19),0),""))+($F$20*ISNUMBER(MATCH('📋 Inventaire Complet'!$F$3:$F$517,{"D4R";"CEPH";"ISTI";"COLCOM";"HTMR"},0))))>0)*((COUNTIF($H$6:$H$10,TRUE)=0)+(($H$6*ISNUMBER(SEARCH($G$6,'📋 Inventaire Complet'!$L$3:$L$517)))+($H$7*ISNUMBER(SEARCH($G$7,'📋 Inventaire Complet'!$L$3:$L$517)))+($H$8*ISNUMBER(SEARCH($G$8,'📋 Inventaire Complet'!$L$3:$L$517)))+($H$9*ISNUMBER(SEARCH($G$9,'📋 Inventaire Complet'!$L$3:$L$517)))+($H$10*ISNUMBER(SEARCH($G$10,'📋 Inventaire Complet'!$L$3:$L$517))))>0)))} -> 1 | AA4: =IF(Y4="",0,Z4+ROW()/10000) -> 1.0004
A5: Thématique | C5: Année | E5: Hub / Laboratoire | G5: Statut | J5: État | K5: Sélection | S5: Green Agriculture & Biotechnology | T5: 2013 | U5: CERPHOS (historique) | V5: Nanomatériaux, céramiques & matériaux fonctionnels | W5: {=SUMPRODUCT(('📋 Inventaire Complet'!$C$3:$C$517=$V5)*(($B$5="Tous")+('📋 Inventaire Complet'!$B$3:$B$517=$B$5)>0)*(($E$5="Toutes")+(LEFT('📋 Inventaire Complet'!$J$3:$J$517,4)=$E$5&"")>0)*(($H$5="Toutes")+('📋 Inventaire Complet'!$F$3:$F$517=$H$5)>0)*(LEN('📋 Inventaire Complet'!$D$3:$D$517)>0)*(($K$5="Tous")+(ISNUMBER(SEARCH($K$5,'📋 Inventaire Complet'!$L$3:$L$517)))>0))} -> 0 | X5: =W5+ROW()/10000 -> 0.0005 | Y5: EL KAMOUNY Khadija; Fatima Ezzahra EL KAMOUNY | Z5: {=IF(Y5="",0,SUMPRODUCT(('📋 Inventaire Complet'!$E$3:$E$517=Y5)*((COUNTIF($B$6:$B$10,TRUE)=0)+ISNUMBER(IFERROR(MATCH('📋 Inventaire Complet'!$B$3:$B$517,IF($B$6:$B$10,$A$6:$A$10),0),""))>0)*((COUNTIF($D$6:$D$22,TRUE)=0)+ISNUMBER(IFERROR(MATCH(LEFT('📋 Inventaire Complet'!$J$3:$J$517,4),IF($D$6:$D$22,$C$6:$C$22&""),0),""))>0)*((COUNTIF($F$6:$F$20,TRUE)=0)+(ISNUMBER(IFERROR(MATCH('📋 Inventaire Complet'!$F$3:$F$517,IF($F$6:$F$19,$E$6:$E$19),0),""))+($F$20*ISNUMBER(MATCH('📋 Inventaire Complet'!$F$3:$F$517,{"D4R";"CEPH";"ISTI";"COLCOM";"HTMR"},0))))>0)*((COUNTIF($H$6:$H$10,TRUE)=0)+(($H$6*ISNUMBER(SEARCH($G$6,'📋 Inventaire Complet'!$L$3:$L$517)))+($H$7*ISNUMBER(SEARCH($G$7,'📋 Inventaire Complet'!$L$3:$L$517)))+($H$8*ISNUMBER(SEARCH($G$8,'📋 Inventaire Complet'!$L$3:$L$517)))+($H$9*ISNUMBER(SEARCH($G$9,'📋 Inventaire Complet'!$L$3:$L$517)))+($H$10*ISNUMBER(SEARCH($G$10,'📋 Inventaire Complet'!$L$3:$L$517))))>0)))} -> 1 | AA5: =IF(Y5="",0,Z5+ROW()/10000) -> 1.0005
A6: Environmental Tech & Digital Mining | B6: FALSE | C6: 2010 | D6: FALSE | E6: MAScIR | F6: FALSE | G6: Maintenu | H6: FALSE | S6: Sustainable Energy Storage & Management | T6: 2014 | U6: ACER CoE | V6: Procédés phosphates, phosphogypse & chimie industrielle | W6: {=SUMPRODUCT(('📋 Inventaire Complet'!$C$3:$C$517=$V6)*(($B$5="Tous")+('📋 Inventaire Complet'!$B$3:$B$517=$B$5)>0)*(($E$5="Toutes")+(LEFT('📋 Inventaire Complet'!$J$3:$J$517,4)=$E$5&"")>0)*(($H$5="Toutes")+('📋 Inventaire Complet'!$F$3:$F$517=$H$5)>0)*(LEN('📋 Inventaire Complet'!$D$3:$D$517)>0)*(($K$5="Tous")+(ISNUMBER(SEARCH($K$5,'📋 Inventaire Complet'!$L$3:$L$517)))>0))} -> 0 | X6: =W6+ROW()/10000 -> 0.0006 | Y6: EL BOURKADI KHADIJA; MERGHOUB NAWAL; QAISS ABOU EL KACEM; BOUHFID RACHID | Z6: {=IF(Y6="",0,SUMPRODUCT(('📋 Inventaire Complet'!$E$3:$E$517=Y6)*((COUNTIF($B$6:$B$10,TRUE)=0)+ISNUMBER(IFERROR(MATCH('📋 Inventaire Complet'!$B$3:$B$517,IF($B$6:$B$10,$A$6:$A$10),0),""))>0)*((COUNTIF($D$6:$D$22,TRUE)=0)+ISNUMBER(IFERROR(MATCH(LEFT('📋 Inventaire Complet'!$J$3:$J$517,4),IF($D$6:$D$22,$C$6:$C$22&""),0),""))>0)*((COUNTIF($F$6:$F$20,TRUE)=0)+(ISNUMBER(IFERROR(MATCH('📋 Inventaire Complet'!$F$3:$F$517,IF($F$6:$F$19,$E$6:$E$19),0),""))+($F$20*ISNUMBER(MATCH('📋 Inventaire Complet'!$F$3:$F$517,{"D4R";"CEPH";"ISTI";"COLCOM";"HTMR"},0))))>0)*((COUNTIF($H$6:$H$10,TRUE)=0)+(($H$6*ISNUMBER(SEARCH($G$6,'📋 Inventaire Complet'!$L$3:$L$517)))+($H$7*ISNUMBER(SEARCH($G$7,'📋 Inventaire Complet'!$L$3:$L$517)))+($H$8*ISNUMBER(SEARCH($G$8,'📋 Inventaire Complet'!$L$3:$L$517)))+($H$9*ISNUMBER(SEARCH($G$9,'📋 Inventaire Complet'!$L$3:$L$517)))+($H$10*ISNUMBER(SEARCH($G$10,'📋 Inventaire Complet'!$L$3:$L$517))))>0)))} -> 1 | AA6: =IF(Y6="",0,Z6+ROW()/10000) -> 1.0006
A7: Mineral Processing & Strategic Synthesis | B7: FALSE | C7: 2011 | D7: FALSE | E7: OCP / CERPHOS (historique) | F7: FALSE | G7: Délivré | H7: FALSE | T7: 2015 | U7: CBS | V7: Traitement de l’eau, effluents & dépollution | W7: {=SUMPRODUCT(('📋 Inventaire Complet'!$C$3:$C$517=$V7)*(($B$5="Tous")+('📋 Inventaire Complet'!$B$3:$B$517=$B$5)>0)*(($E$5="Toutes")+(LEFT('📋 Inventaire Complet'!$J$3:$J$517,4)=$E$5&"")>0)*(($H$5="Toutes")+('📋 Inventaire Complet'!$F$3:$F$517=$H$5)>0)*(LEN('📋 Inventaire Complet'!$D$3:$D$517)>0)*(($K$5="Tous")+(ISNUMBER(SEARCH($K$5,'📋 Inventaire Complet'!$L$3:$L$517)))>0))} -> 0 | X7: =W7+ROW()/10000 -> 0.0007 | Y7: Hassan AIT BENHASSOU, Abdeladim MOUMEN, Hicham EL HADI, El Mehdi BENTALEB | Z7: {=IF(Y7="",0,SUMPRODUCT(('📋 Inventaire Complet'!$E$3:$E$517=Y7)*((COUNTIF($B$6:$B$10,TRUE)=0)+ISNUMBER(IFERROR(MATCH('📋 Inventaire Complet'!$B$3:$B$517,IF($B$6:$B$10,$A$6:$A$10),0),""))>0)*((COUNTIF($D$6:$D$22,TRUE)=0)+ISNUMBER(IFERROR(MATCH(LEFT('📋 Inventaire Complet'!$J$3:$J$517,4),IF($D$6:$D$22,$C$6:$C$22&""),0),""))>0)*((COUNTIF($F$6:$F$20,TRUE)=0)+(ISNUMBER(IFERROR(MATCH('📋 Inventaire Complet'!$F$3:$F$517,IF($F$6:$F$19,$E$6:$E$19),0),""))+($F$20*ISNUMBER(MATCH('📋 Inventaire Complet'!$F$3:$F$517,{"D4R";"CEPH";"ISTI";"COLCOM";"HTMR"},0))))>0)*((COUNTIF($H$6:$H$10,TRUE)=0)+(($H$6*ISNUMBER(SEARCH($G$6,'📋 Inventaire Complet'!$L$3:$L$517)))+($H$7*ISNUMBER(SEARCH($G$7,'📋 Inventaire Complet'!$L$3:$L$517)))+($H$8*ISNUMBER(SEARCH($G$8,'📋 Inventaire Complet'!$L$3:$L$517)))+($H$9*ISNUMBER(SEARCH($G$9,'📋 Inventaire Complet'!$L$3:$L$517)))+($H$10*ISNUMBER(SEARCH($G$10,'📋 Inventaire Complet'!$L$3:$L$517))))>0)))} -> 1 | AA7: =IF(Y7="",0,Z7+ROW()/10000) -> 1.0007
A8: Circular Chemistry & Waste Valorization | B8: FALSE | C8: 2012 | D8: FALSE | E8: MSN | F8: FALSE | G8: PCT | H8: FALSE | Y8: Ressami, Ait Benhassou, Lakssir | Z8: {=IF(Y8="",0,SUMPRODUCT(('📋 Inventaire Complet'!$E$3:$E$517=Y8)*((COUNTIF($B$6:$B$10,TRUE)=0)+ISNUMBER(IFERROR(MATCH('📋 Inventaire Complet'!$B$3:$B$517,IF($B$6:$B$10,$A$6:$A$10),0),""))>0)*((COUNTIF($D$6:$D$22,TRUE)=0)+ISNUMBER(IFERROR(MATCH(LEFT('📋 Inventaire Complet'!$J$3:$J$517,4),IF($D$6:$D$22,$C$6:$C$22&""),0),""))>0)*((COUNTIF($F$6:$F$20,TRUE)=0)+(ISNUMBER(IFERROR(MATCH('📋 Inventaire Complet'!$F$3:$F$517,IF($F$6:$F$19,$E$6:$E$19),0),""))+($F$20*ISNUMBER(MATCH('📋 Inventaire Complet'!$F$3:$F$517,{"D4R";"CEPH";"ISTI";"COLCOM";"HTMR"},0))))>0)*((COUNTIF($H$6:$H$10,TRUE)=0)+(($H$6*ISNUMBER(SEARCH($G$6,'📋 Inventaire Complet'!$L$3:$L$517)))+($H$7*ISNUMBER(SEARCH($G$7,'📋 Inventaire Complet'!$L$3:$L$517)))+($H$8*ISNUMBER(SEARCH($G$8,'📋 Inventaire Complet'!$L$3:$L$517)))+($H$9*ISNUMBER(SEARCH($G$9,'📋 Inventaire Complet'!$L$3:$L$517)))+($H$10*ISNUMBER(SEARCH($G$10,'📋 Inventaire Complet'!$L$3:$L$517))))>0)))} -> 1 | AA8: =IF(Y8="",0,Z8+ROW()/10000) -> 1.0008
A9: Green Agriculture & Biotechnology | B9: FALSE | C9: 2013 | D9: FALSE | E9: CERPHOS (historique) | F9: FALSE | G9: OMPIC | H9: FALSE | Y9: BOUHFID RACHID QAISS ABOU EL KACEM MERGHOUB NAWAL Mekhzoum Mohamed El Mehdi EL BOURAKADI KHADIJA | Z9: {=IF(Y9="",0,SUMPRODUCT(('📋 Inventaire Complet'!$E$3:$E$517=Y9)*((COUNTIF($B$6:$B$10,TRUE)=0)+ISNUMBER(IFERROR(MATCH('📋 Inventaire Complet'!$B$3:$B$517,IF($B$6:$B$10,$A$6:$A$10),0),""))>0)*((COUNTIF($D$6:$D$22,TRUE)=0)+ISNUMBER(IFERROR(MATCH(LEFT('📋 Inventaire Complet'!$J$3:$J$517,4),IF($D$6:$D$22,$C$6:$C$22&""),0),""))>0)*((COUNTIF($F$6:$F$20,TRUE)=0)+(ISNUMBER(IFERROR(MATCH('📋 Inventaire Complet'!$F$3:$F$517,IF($F$6:$F$19,$E$6:$E$19),0),""))+($F$20*ISNUMBER(MATCH('📋 Inventaire Complet'!$F$3:$F$517,{"D4R";"CEPH";"ISTI";"COLCOM";"HTMR"},0))))>0)*((COUNTIF($H$6:$H$10,TRUE)=0)+(($H$6*ISNUMBER(SEARCH($G$6,'📋 Inventaire Complet'!$L$3:$L$517)))+($H$7*ISNUMBER(SEARCH($G$7,'📋 Inventaire Complet'!$L$3:$L$517)))+($H$8*ISNUMBER(SEARCH($G$8,'📋 Inventaire Complet'!$L$3:$L$517)))+($H$9*ISNUMBER(SEARCH($G$9,'📋 Inventaire Complet'!$L$3:$L$517)))+($H$10*ISNUMBER(SEARCH($G$10,'📋 Inventaire Complet'!$L$3:$L$517))))>0)))} -> 2 | AA9: =IF(Y9="",0,Z9+ROW()/10000) -> 2.0009
A10: Sustainable Energy Storage & Management | B10: FALSE | C10: 2014 | D10: FALSE | E10: ACER CoE | F10: FALSE | G10: Abandonné | H10: FALSE | Y10: EL BOURKADI KHADIJA; ESSASSI EL MOKHTAR; QAISS ABOU EL KACEM; BOUHFID RACHID | Z10: {=IF(Y10="",0,SUMPRODUCT(('📋 Inventaire Complet'!$E$3:$E$517=Y10)*((COUNTIF($B$6:$B$10,TRUE)=0)+ISNUMBER(IFERROR(MATCH('📋 Inventaire Complet'!$B$3:$B$517,IF($B$6:$B$10,$A$6:$A$10),0),""))>0)*((COUNTIF($D$6:$D$22,TRUE)=0)+ISNUMBER(IFERROR(MATCH(LEFT('📋 Inventaire Complet'!$J$3:$J$517,4),IF($D$6:$D$22,$C$6:$C$22&""),0),""))>0)*((COUNTIF($F$6:$F$20,TRUE)=0)+(ISNUMBER(IFERROR(MATCH('📋 Inventaire Complet'!$F$3:$F$517,IF($F$6:$F$19,$E$6:$E$19),0),""))+($F$20*ISNUMBER(MATCH('📋 Inventaire Complet'!$F$3:$F$517,{"D4R";"CEPH";"ISTI";"COLCOM";"HTMR"},0))))>0)*((COUNTIF($H$6:$H$10,TRUE)=0)+(($H$6*ISNUMBER(SEARCH($G$6,'📋 Inventaire Complet'!$L$3:$L$517)))+($H$7*ISNUMBER(SEARCH($G$7,'📋 Inventaire Complet'!$L$3:$L$517)))+($H$8*ISNUMBER(SEARCH($G$8,'📋 Inventaire Complet'!$L$3:$L$517)))+($H$9*ISNUMBER(SEARCH($G$9,'📋 Inventaire Complet'!$L$3:$L$517)))+($H$10*ISNUMBER(SEARCH($G$10,'📋 Inventaire Complet'!$L$3:$L$517))))>0)))} -> 1 | AA10: =IF(Y10="",0,Z10+ROW()/10000) -> 1.001
C11: 2015 | D11: FALSE | E11: CBS | F11: FALSE | Y11: ISSAM, KASMI YASSINE | Z11: {=IF(Y11="",0,SUMPRODUCT(('📋 Inventaire Complet'!$E$3:$E$517=Y11)*((COUNTIF($B$6:$B$10,TRUE)=0)+ISNUMBER(IFERROR(MATCH('📋 Inventaire Complet'!$B$3:$B$517,IF($B$6:$B$10,$A$6:$A$10),0),""))>0)*((COUNTIF($D$6:$D$22,TRUE)=0)+ISNUMBER(IFERROR(MATCH(LEFT('📋 Inventaire Complet'!$J$3:$J$517,4),IF($D$6:$D$22,$C$6:$C$22&""),0),""))>0)*((COUNTIF($F$6:$F$20,TRUE)=0)+(ISNUMBER(IFERROR(MATCH('📋 Inventaire Complet'!$F$3:$F$517,IF($F$6:$F$19,$E$6:$E$19),0),""))+($F$20*ISNUMBER(MATCH('📋 Inventaire Complet'!$F$3:$F$517,{"D4R";"CEPH";"ISTI";"COLCOM";"HTMR"},0))))>0)*((COUNTIF($H$6:$H$10,TRUE)=0)+(($H$6*ISNUMBER(SEARCH($G$6,'📋 Inventaire Complet'!$L$3:$L$517)))+($H$7*ISNUMBER(SEARCH($G$7,'📋 Inventaire Complet'!$L$3:$L$517)))+($H$8*ISNUMBER(SEARCH($G$8,'📋 Inventaire Complet'!$L$3:$L$517)))+($H$9*ISNUMBER(SEARCH($G$9,'📋 Inventaire Complet'!$L$3:$L$517)))+($H$10*ISNUMBER(SEARCH($G$10,'📋 Inventaire Complet'!$L$3:$L$517))))>0)))} -> 1 | AA11: =IF(Y11="",0,Z11+ROW()/10000) -> 1.0011
C12: 2016 | D12: FALSE | E12: ASARI | F12: FALSE | Y12: Sbihi Younes; Qmichou Zineb; El Abbadi Najia; El Mzibri Mohammed; Sefrioui Hassan | Z12: {=IF(Y12="",0,SUMPRODUCT(('📋 Inventaire Complet'!$E$3:$E$517=Y12)*((COUNTIF($B$6:$B$10,TRUE)=0)+ISNUMBER(IFERROR(MATCH('📋 Inventaire Complet'!$B$3:$B$517,IF($B$6:$B$10,$A$6:$A$10),0),""))>0)*((COUNTIF($D$6:$D$22,TRUE)=0)+ISNUMBER(IFERROR(MATCH(LEFT('📋 Inventaire Complet'!$J$3:$J$517,4),IF($D$6:$D$22,$C$6:$C$22&""),0),""))>0)*((COUNTIF($F$6:$F$20,TRUE)=0)+(ISNUMBER(IFERROR(MATCH('📋 Inventaire Complet'!$F$3:$F$517,IF($F$6:$F$19,$E$6:$E$19),0),""))+($F$20*ISNUMBER(MATCH('📋 Inventaire Complet'!$F$3:$F$517,{"D4R";"CEPH";"ISTI";"COLCOM";"HTMR"},0))))>0)*((COUNTIF($H$6:$H$10,TRUE)=0)+(($H$6*ISNUMBER(SEARCH($G$6,'📋 Inventaire Complet'!$L$3:$L$517)))+($H$7*ISNUMBER(SEARCH($G$7,'📋 Inventaire Complet'!$L$3:$L$517)))+($H$8*ISNUMBER(SEARCH($G$8,'📋 Inventaire Complet'!$L$3:$L$517)))+($H$9*ISNUMBER(SEARCH($G$9,'📋 Inventaire Complet'!$L$3:$L$517)))+($H$10*ISNUMBER(SEARCH($G$10,'📋 Inventaire Complet'!$L$3:$L$517))))>0)))} -> 1 | AA12: =IF(Y12="",0,Z12+ROW()/10000) -> 1.0012
C13: 2017 | D13: FALSE | E13: GTI | F13: FALSE | Y13: AIT BENHASSOU, BENTALEB, SEFRIOUI | Z13: {=IF(Y13="",0,SUMPRODUCT(('📋 Inventaire Complet'!$E$3:$E$517=Y13)*((COUNTIF($B$6:$B$10,TRUE)=0)+ISNUMBER(IFERROR(MATCH('📋 Inventaire Complet'!$B$3:$B$517,IF($B$6:$B$10,$A$6:$A$10),0),""))>0)*((COUNTIF($D$6:$D$22,TRUE)=0)+ISNUMBER(IFERROR(MATCH(LEFT('📋 Inventaire Complet'!$J$3:$J$517,4),IF($D$6:$D$22,$C$6:$C$22&""),0),""))>0)*((COUNTIF($F$6:$F$20,TRUE)=0)+(ISNUMBER(IFERROR(MATCH('📋 Inventaire Complet'!$F$3:$F$517,IF($F$6:$F$19,$E$6:$E$19),0),""))+($F$20*ISNUMBER(MATCH('📋 Inventaire Complet'!$F$3:$F$517,{"D4R";"CEPH";"ISTI";"COLCOM";"HTMR"},0))))>0)*((COUNTIF($H$6:$H$10,TRUE)=0)+(($H$6*ISNUMBER(SEARCH($G$6,'📋 Inventaire Complet'!$L$3:$L$517)))+($H$7*ISNUMBER(SEARCH($G$7,'📋 Inventaire Complet'!$L$3:$L$517)))+($H$8*ISNUMBER(SEARCH($G$8,'📋 Inventaire Complet'!$L$3:$L$517)))+($H$9*ISNUMBER(SEARCH($G$9,'📋 Inventaire Complet'!$L$3:$L$517)))+($H$10*ISNUMBER(SEARCH($G$10,'📋 Inventaire Complet'!$L$3:$L$517))))>0)))} -> 4 | AA13: =IF(Y13="",0,Z13+ROW()/10000) -> 4.0013
C14: 2018 | D14: FALSE | E14: GSMI | F14: FALSE | Y14: WAHBY, MERGHOUB | Z14: {=IF(Y14="",0,SUMPRODUCT(('📋 Inventaire Complet'!$E$3:$E$517=Y14)*((COUNTIF($B$6:$B$10,TRUE)=0)+ISNUMBER(IFERROR(MATCH('📋 Inventaire Complet'!$B$3:$B$517,IF($B$6:$B$10,$A$6:$A$10),0),""))>0)*((COUNTIF($D$6:$D$22,TRUE)=0)+ISNUMBER(IFERROR(MATCH(LEFT('📋 Inventaire Complet'!$J$3:$J$517,4),IF($D$6:$D$22,$C$6:$C$22&""),0),""))>0)*((COUNTIF($F$6:$F$20,TRUE)=0)+(ISNUMBER(IFERROR(MATCH('📋 Inventaire Complet'!$F$3:$F$517,IF($F$6:$F$19,$E$6:$E$19),0),""))+($F$20*ISNUMBER(MATCH('📋 Inventaire Complet'!$F$3:$F$517,{"D4R";"CEPH";"ISTI";"COLCOM";"HTMR"},0))))>0)*((COUNTIF($H$6:$H$10,TRUE)=0)+(($H$6*ISNUMBER(SEARCH($G$6,'📋 Inventaire Complet'!$L$3:$L$517)))+($H$7*ISNUMBER(SEARCH($G$7,'📋 Inventaire Complet'!$L$3:$L$517)))+($H$8*ISNUMBER(SEARCH($G$8,'📋 Inventaire Complet'!$L$3:$L$517)))+($H$9*ISNUMBER(SEARCH($G$9,'📋 Inventaire Complet'!$L$3:$L$517)))+($H$10*ISNUMBER(SEARCH($G$10,'📋 Inventaire Complet'!$L$3:$L$517))))>0)))} -> 1 | AA14: =IF(Y14="",0,Z14+ROW()/10000) -> 1.0014
C15: 2019 | D15: FALSE | E15: LIMSET | F15: FALSE | Y15: DMITRY, SEKKAT | Z15: {=IF(Y15="",0,SUMPRODUCT(('📋 Inventaire Complet'!$E$3:$E$517=Y15)*((COUNTIF($B$6:$B$10,TRUE)=0)+ISNUMBER(IFERROR(MATCH('📋 Inventaire Complet'!$B$3:$B$517,IF($B$6:$B$10,$A$6:$A$10),0),""))>0)*((COUNTIF($D$6:$D$22,TRUE)=0)+ISNUMBER(IFERROR(MATCH(LEFT('📋 Inventaire Complet'!$J$3:$J$517,4),IF($D$6:$D$22,$C$6:$C$22&""),0),""))>0)*((COUNTIF($F$6:$F$20,TRUE)=0)+(ISNUMBER(IFERROR(MATCH('📋 Inventaire Complet'!$F$3:$F$517,IF($F$6:$F$19,$E$6:$E$19),0),""))+($F$20*ISNUMBER(MATCH('📋 Inventaire Complet'!$F$3:$F$517,{"D4R";"CEPH";"ISTI";"COLCOM";"HTMR"},0))))>0)*((COUNTIF($H$6:$H$10,TRUE)=0)+(($H$6*ISNUMBER(SEARCH($G$6,'📋 Inventaire Complet'!$L$3:$L$517)))+($H$7*ISNUMBER(SEARCH($G$7,'📋 Inventaire Complet'!$L$3:$L$517)))+($H$8*ISNUMBER(SEARCH($G$8,'📋 Inventaire Complet'!$L$3:$L$517)))+($H$9*ISNUMBER(SEARCH($G$9,'📋 Inventaire Complet'!$L$3:$L$517)))+($H$10*ISNUMBER(SEARCH($G$10,'📋 Inventaire Complet'!$L$3:$L$517))))>0)))} -> 1 | AA15: =IF(Y15="",0,Z15+ROW()/10000) -> 1.0015
C16: 2020 | D16: FALSE | E16: DICE | F16: FALSE | Y16: Shinji HAYASHI Zouheir SEKKAT Dmitry V. NESTERENKO | Z16: {=IF(Y16="",0,SUMPRODUCT(('📋 Inventaire Complet'!$E$3:$E$517=Y16)*((COUNTIF($B$6:$B$10,TRUE)=0)+ISNUMBER(IFERROR(MATCH('📋 Inventaire Complet'!$B$3:$B$517,IF($B$6:$B$10,$A$6:$A$10),0),""))>0)*((COUNTIF($D$6:$D$22,TRUE)=0)+ISNUMBER(IFERROR(MATCH(LEFT('📋 Inventaire Complet'!$J$3:$J$517,4),IF($D$6:$D$22,$C$6:$C$22&""),0),""))>0)*((COUNTIF($F$6:$F$20,TRUE)=0)+(ISNUMBER(IFERROR(MATCH('📋 Inventaire Complet'!$F$3:$F$517,IF($F$6:$F$19,$E$6:$E$19),0),""))+($F$20*ISNUMBER(MATCH('📋 Inventaire Complet'!$F$3:$F$517,{"D4R";"CEPH";"ISTI";"COLCOM";"HTMR"},0))))>0)*((COUNTIF($H$6:$H$10,TRUE)=0)+(($H$6*ISNUMBER(SEARCH($G$6,'📋 Inventaire Complet'!$L$3:$L$517)))+($H$7*ISNUMBER(SEARCH($G$7,'📋 Inventaire Complet'!$L$3:$L$517)))+($H$8*ISNUMBER(SEARCH($G$8,'📋 Inventaire Complet'!$L$3:$L$517)))+($H$9*ISNUMBER(SEARCH($G$9,'📋 Inventaire Complet'!$L$3:$L$517)))+($H$10*ISNUMBER(SEARCH($G$10,'📋 Inventaire Complet'!$L$3:$L$517))))>0)))} -> 1 | AA16: =IF(Y16="",0,Z16+ROW()/10000) -> 1.0016
C17: 2021 | D17: FALSE | E17: TechCell | F17: FALSE | Y17: LAHLALIA Ayoub; Khadija EL KAMOUNY | Z17: {=IF(Y17="",0,SUMPRODUCT(('📋 Inventaire Complet'!$E$3:$E$517=Y17)*((COUNTIF($B$6:$B$10,TRUE)=0)+ISNUMBER(IFERROR(MATCH('📋 Inventaire Complet'!$B$3:$B$517,IF($B$6:$B$10,$A$6:$A$10),0),""))>0)*((COUNTIF($D$6:$D$22,TRUE)=0)+ISNUMBER(IFERROR(MATCH(LEFT('📋 Inventaire Complet'!$J$3:$J$517,4),IF($D$6:$D$22,$C$6:$C$22&""),0),""))>0)*((COUNTIF($F$6:$F$20,TRUE)=0)+(ISNUMBER(IFERROR(MATCH('📋 Inventaire Complet'!$F$3:$F$517,IF($F$6:$F$19,$E$6:$E$19),0),""))+($F$20*ISNUMBER(MATCH('📋 Inventaire Complet'!$F$3:$F$517,{"D4R";"CEPH";"ISTI";"COLCOM";"HTMR"},0))))>0)*((COUNTIF($H$6:$H$10,TRUE)=0)+(($H$6*ISNUMBER(SEARCH($G$6,'📋 Inventaire Complet'!$L$3:$L$517)))+($H$7*ISNUMBER(SEARCH($G$7,'📋 Inventaire Complet'!$L$3:$L$517)))+($H$8*ISNUMBER(SEARCH($G$8,'📋 Inventaire Complet'!$L$3:$L$517)))+($H$9*ISNUMBER(SEARCH($G$9,'📋 Inventaire Complet'!$L$3:$L$517)))+($H$10*ISNUMBER(SEARCH($G$10,'📋 Inventaire Complet'!$L$3:$L$517))))>0)))} -> 1 | AA17: =IF(Y17="",0,Z17+ROW()/10000) -> 1.0017
C18: 2022 | D18: FALSE | E18: ILO | F18: FALSE | Y18: LAHLALIA Ayoub; EL KAMOUNY Khadija | Z18: {=IF(Y18="",0,SUMPRODUCT(('📋 Inventaire Complet'!$E$3:$E$517=Y18)*((COUNTIF($B$6:$B$10,TRUE)=0)+ISNUMBER(IFERROR(MATCH('📋 Inventaire Complet'!$B$3:$B$517,IF($B$6:$B$10,$A$6:$A$10),0),""))>0)*((COUNTIF($D$6:$D$22,TRUE)=0)+ISNUMBER(IFERROR(MATCH(LEFT('📋 Inventaire Complet'!$J$3:$J$517,4),IF($D$6:$D$22,$C$6:$C$22&""),0),""))>0)*((COUNTIF($F$6:$F$20,TRUE)=0)+(ISNUMBER(IFERROR(MATCH('📋 Inventaire Complet'!$F$3:$F$517,IF($F$6:$F$19,$E$6:$E$19),0),""))+($F$20*ISNUMBER(MATCH('📋 Inventaire Complet'!$F$3:$F$517,{"D4R";"CEPH";"ISTI";"COLCOM";"HTMR"},0))))>0)*((COUNTIF($H$6:$H$10,TRUE)=0)+(($H$6*ISNUMBER(SEARCH($G$6,'📋 Inventaire Complet'!$L$3:$L$517)))+($H$7*ISNUMBER(SEARCH($G$7,'📋 Inventaire Complet'!$L$3:$L$517)))+($H$8*ISNUMBER(SEARCH($G$8,'📋 Inventaire Complet'!$L$3:$L$517)))+($H$9*ISNUMBER(SEARCH($G$9,'📋 Inventaire Complet'!$L$3:$L$517)))+($H$10*ISNUMBER(SEARCH($G$10,'📋 Inventaire Complet'!$L$3:$L$517))))>0)))} -> 1 | AA18: =IF(Y18="",0,Z18+ROW()/10000) -> 1.0018
C19: 2023 | D19: FALSE | E19: Al-Moutmir | F19: FALSE | Y19: Zouheir Sekkat Dmitry V. Nesterenko | Z19: {=IF(Y19="",0,SUMPRODUCT(('📋 Inventaire Complet'!$E$3:$E$517=Y19)*((COUNTIF($B$6:$B$10,TRUE)=0)+ISNUMBER(IFERROR(MATCH('📋 Inventaire Complet'!$B$3:$B$517,IF($B$6:$B$10,$A$6:$A$10),0),""))>0)*((COUNTIF($D$6:$D$22,TRUE)=0)+ISNUMBER(IFERROR(MATCH(LEFT('📋 Inventaire Complet'!$J$3:$J$517,4),IF($D$6:$D$22,$C$6:$C$22&""),0),""))>0)*((COUNTIF($F$6:$F$20,TRUE)=0)+(ISNUMBER(IFERROR(MATCH('📋 Inventaire Complet'!$F$3:$F$517,IF($F$6:$F$19,$E$6:$E$19),0),""))+($F$20*ISNUMBER(MATCH('📋 Inventaire Complet'!$F$3:$F$517,{"D4R";"CEPH";"ISTI";"COLCOM";"HTMR"},0))))>0)*((COUNTIF($H$6:$H$10,TRUE)=0)+(($H$6*ISNUMBER(SEARCH($G$6,'📋 Inventaire Complet'!$L$3:$L$517)))+($H$7*ISNUMBER(SEARCH($G$7,'📋 Inventaire Complet'!$L$3:$L$517)))+($H$8*ISNUMBER(SEARCH($G$8,'📋 Inventaire Complet'!$L$3:$L$517)))+($H$9*ISNUMBER(SEARCH($G$9,'📋 Inventaire Complet'!$L$3:$L$517)))+($H$10*ISNUMBER(SEARCH($G$10,'📋 Inventaire Complet'!$L$3:$L$517))))>0)))} -> 1 | AA19: =IF(Y19="",0,Z19+ROW()/10000) -> 1.0019
C20: 2024 | D20: FALSE | E20: Autres (D4R/CEPH/ISTI/COLCOM/HTMR) | F20: FALSE | Y20: Zouheir SEKKAT Dmitry NESTERENKO | Z20: {=IF(Y20="",0,SUMPRODUCT(('📋 Inventaire Complet'!$E$3:$E$517=Y20)*((COUNTIF($B$6:$B$10,TRUE)=0)+ISNUMBER(IFERROR(MATCH('📋 Inventaire Complet'!$B$3:$B$517,IF($B$6:$B$10,$A$6:$A$10),0),""))>0)*((COUNTIF($D$6:$D$22,TRUE)=0)+ISNUMBER(IFERROR(MATCH(LEFT('📋 Inventaire Complet'!$J$3:$J$517,4),IF($D$6:$D$22,$C$6:$C$22&""),0),""))>0)*((COUNTIF($F$6:$F$20,TRUE)=0)+(ISNUMBER(IFERROR(MATCH('📋 Inventaire Complet'!$F$3:$F$517,IF($F$6:$F$19,$E$6:$E$19),0),""))+($F$20*ISNUMBER(MATCH('📋 Inventaire Complet'!$F$3:$F$517,{"D4R";"CEPH";"ISTI";"COLCOM";"HTMR"},0))))>0)*((COUNTIF($H$6:$H$10,TRUE)=0)+(($H$6*ISNUMBER(SEARCH($G$6,'📋 Inventaire Complet'!$L$3:$L$517)))+($H$7*ISNUMBER(SEARCH($G$7,'📋 Inventaire Complet'!$L$3:$L$517)))+($H$8*ISNUMBER(SEARCH($G$8,'📋 Inventaire Complet'!$L$3:$L$517)))+($H$9*ISNUMBER(SEARCH($G$9,'📋 Inventaire Complet'!$L$3:$L$517)))+($H$10*ISNUMBER(SEARCH($G$10,'📋 Inventaire Complet'!$L$3:$L$517))))>0)))} -> 1 | AA20: =IF(Y20="",0,Z20+ROW()/10000) -> 1.002
C21: 2025 | D21: FALSE | Y21: Ouadi SAIDI Ilham BOUZIDA Brahim LAKSSIR Reda RABIE | Z21: {=IF(Y21="",0,SUMPRODUCT(('📋 Inventaire Complet'!$E$3:$E$517=Y21)*((COUNTIF($B$6:$B$10,TRUE)=0)+ISNUMBER(IFERROR(MATCH('📋 Inventaire Complet'!$B$3:$B$517,IF($B$6:$B$10,$A$6:$A$10),0),""))>0)*((COUNTIF($D$6:$D$22,TRUE)=0)+ISNUMBER(IFERROR(MATCH(LEFT('📋 Inventaire Complet'!$J$3:$J$517,4),IF($D$6:$D$22,$C$6:$C$22&""),0),""))>0)*((COUNTIF($F$6:$F$20,TRUE)=0)+(ISNUMBER(IFERROR(MATCH('📋 Inventaire Complet'!$F$3:$F$517,IF($F$6:$F$19,$E$6:$E$19),0),""))+($F$20*ISNUMBER(MATCH('📋 Inventaire Complet'!$F$3:$F$517,{"D4R";"CEPH";"ISTI";"COLCOM";"HTMR"},0))))>0)*((COUNTIF($H$6:$H$10,TRUE)=0)+(($H$6*ISNUMBER(SEARCH($G$6,'📋 Inventaire Complet'!$L$3:$L$517)))+($H$7*ISNUMBER(SEARCH($G$7,'📋 Inventaire Complet'!$L$3:$L$517)))+($H$8*ISNUMBER(SEARCH($G$8,'📋 Inventaire Complet'!$L$3:$L$517)))+($H$9*ISNUMBER(SEARCH($G$9,'📋 Inventaire Complet'!$L$3:$L$517)))+($H$10*ISNUMBER(SEARCH($G$10,'📋 Inventaire Complet'!$L$3:$L$517))))>0)))} -> 1 | AA21: =IF(Y21="",0,Z21+ROW()/10000) -> 1.0021
C22: 2026 | D22: FALSE | Y22: Rachid Benani, Brahim Lakssir, Abdelhafid ALMATROUCH | Z22: {=IF(Y22="",0,SUMPRODUCT(('📋 Inventaire Complet'!$E$3:$E$517=Y22)*((COUNTIF($B$6:$B$10,TRUE)=0)+ISNUMBER(IFERROR(MATCH('📋 Inventaire Complet'!$B$3:$B$517,IF($B$6:$B$10,$A$6:$A$10),0),""))>0)*((COUNTIF($D$6:$D$22,TRUE)=0)+ISNUMBER(IFERROR(MATCH(LEFT('📋 Inventaire Complet'!$J$3:$J$517,4),IF($D$6:$D$22,$C$6:$C$22&""),0),""))>0)*((COUNTIF($F$6:$F$20,TRUE)=0)+(ISNUMBER(IFERROR(MATCH('📋 Inventaire Complet'!$F$3:$F$517,IF($F$6:$F$19,$E$6:$E$19),0),""))+($F$20*ISNUMBER(MATCH('📋 Inventaire Complet'!$F$3:$F$517,{"D4R";"CEPH";"ISTI";"COLCOM";"HTMR"},0))))>0)*((COUNTIF($H$6:$H$10,TRUE)=0)+(($H$6*ISNUMBER(SEARCH($G$6,'📋 Inventaire Complet'!$L$3:$L$517)))+($H$7*ISNUMBER(SEARCH($G$7,'📋 Inventaire Complet'!$L$3:$L$517)))+($H$8*ISNUMBER(SEARCH($G$8,'📋 Inventaire Complet'!$L$3:$L$517)))+($H$9*ISNUMBER(SEARCH($G$9,'📋 Inventaire Complet'!$L$3:$L$517)))+($H$10*ISNUMBER(SEARCH($G$10,'📋 Inventaire Complet'!$L$3:$L$517))))>0)))} -> 1 | AA22: =IF(Y22="",0,Z22+ROW()/10000) -> 1.0022
Y23: Zouheir SEKKAT Zakaria LAGHFOUR Safae AAZOU | Z23: {=IF(Y23="",0,SUMPRODUCT(('📋 Inventaire Complet'!$E$3:$E$517=Y23)*((COUNTIF($B$6:$B$10,TRUE)=0)+ISNUMBER(IFERROR(MATCH('📋 Inventaire Complet'!$B$3:$B$517,IF($B$6:$B$10,$A$6:$A$10),0),""))>0)*((COUNTIF($D$6:$D$22,TRUE)=0)+ISNUMBER(IFERROR(MATCH(LEFT('📋 Inventaire Complet'!$J$3:$J$517,4),IF($D$6:$D$22,$C$6:$C$22&""),0),""))>0)*((COUNTIF($F$6:$F$20,TRUE)=0)+(ISNUMBER(IFERROR(MATCH('📋 Inventaire Complet'!$F$3:$F$517,IF($F$6:$F$19,$E$6:$E$19),0),""))+($F$20*ISNUMBER(MATCH('📋 Inventaire Complet'!$F$3:$F$517,{"D4R";"CEPH";"ISTI";"COLCOM";"HTMR"},0))))>0)*((COUNTIF($H$6:$H$10,TRUE)=0)+(($H$6*ISNUMBER(SEARCH($G$6,'📋 Inventaire Complet'!$L$3:$L$517)))+($H$7*ISNUMBER(SEARCH($G$7,'📋 Inventaire Complet'!$L$3:$L$517)))+($H$8*ISNUMBER(SEARCH($G$8,'📋 Inventaire Complet'!$L$3:$L$517)))+($H$9*ISNUMBER(SEARCH($G$9,'📋 Inventaire Complet'!$L$3:$L$517)))+($H$10*ISNUMBER(SEARCH($G$10,'📋 Inventaire Complet'!$L$3:$L$517))))>0)))} -> 1 | AA23: =IF(Y23="",0,Z23+ROW()/10000) -> 1.0023
Y24: Rahmouni Anouar Mahboub Oussama Sekkat Zouheir | Z24: {=IF(Y24="",0,SUMPRODUCT(('📋 Inventaire Complet'!$E$3:$E$517=Y24)*((COUNTIF($B$6:$B$10,TRUE)=0)+ISNUMBER(IFERROR(MATCH('📋 Inventaire Complet'!$B$3:$B$517,IF($B$6:$B$10,$A$6:$A$10),0),""))>0)*((COUNTIF($D$6:$D$22,TRUE)=0)+ISNUMBER(IFERROR(MATCH(LEFT('📋 Inventaire Complet'!$J$3:$J$517,4),IF($D$6:$D$22,$C$6:$C$22&""),0),""))>0)*((COUNTIF($F$6:$F$20,TRUE)=0)+(ISNUMBER(IFERROR(MATCH('📋 Inventaire Complet'!$F$3:$F$517,IF($F$6:$F$19,$E$6:$E$19),0),""))+($F$20*ISNUMBER(MATCH('📋 Inventaire Complet'!$F$3:$F$517,{"D4R";"CEPH";"ISTI";"COLCOM";"HTMR"},0))))>0)*((COUNTIF($H$6:$H$10,TRUE)=0)+(($H$6*ISNUMBER(SEARCH($G$6,'📋 Inventaire Complet'!$L$3:$L$517)))+($H$7*ISNUMBER(SEARCH($G$7,'📋 Inventaire Complet'!$L$3:$L$517)))+($H$8*ISNUMBER(SEARCH($G$8,'📋 Inventaire Complet'!$L$3:$L$517)))+($H$9*ISNUMBER(SEARCH($G$9,'📋 Inventaire Complet'!$L$3:$L$517)))+($H$10*ISNUMBER(SEARCH($G$10,'📋 Inventaire Complet'!$L$3:$L$517))))>0)))} -> 1 | AA24: =IF(Y24="",0,Z24+ROW()/10000) -> 1.0024
Y25: BOURJA OMAR; ZENNAYI YAHYA; KABBAJ KAOUTAR | Z25: {=IF(Y25="",0,SUMPRODUCT(('📋 Inventaire Complet'!$E$3:$E$517=Y25)*((COUNTIF($B$6:$B$10,TRUE)=0)+ISNUMBER(IFERROR(MATCH('📋 Inventaire Complet'!$B$3:$B$517,IF($B$6:$B$10,$A$6:$A$10),0),""))>0)*((COUNTIF($D$6:$D$22,TRUE)=0)+ISNUMBER(IFERROR(MATCH(LEFT('📋 Inventaire Complet'!$J$3:$J$517,4),IF($D$6:$D$22,$C$6:$C$22&""),0),""))>0)*((COUNTIF($F$6:$F$20,TRUE)=0)+(ISNUMBER(IFERROR(MATCH('📋 Inventaire Complet'!$F$3:$F$517,IF($F$6:$F$19,$E$6:$E$19),0),""))+($F$20*ISNUMBER(MATCH('📋 Inventaire Complet'!$F$3:$F$517,{"D4R";"CEPH";"ISTI";"COLCOM";"HTMR"},0))))>0)*((COUNTIF($H$6:$H$10,TRUE)=0)+(($H$6*ISNUMBER(SEARCH($G$6,'📋 Inventaire Complet'!$L$3:$L$517)))+($H$7*ISNUMBER(SEARCH($G$7,'📋 Inventaire Complet'!$L$3:$L$517)))+($H$8*ISNUMBER(SEARCH($G$8,'📋 Inventaire Complet'!$L$3:$L$517)))+($H$9*ISNUMBER(SEARCH($G$9,'📋 Inventaire Complet'!$L$3:$L$517)))+($H$10*ISNUMBER(SEARCH($G$10,'📋 Inventaire Complet'!$L$3:$L$517))))>0)))} -> 1 | AA25: =IF(Y25="",0,Z25+ROW()/10000) -> 1.0025
A26: INDICATEURS CLÉS DE PERFORMANCE | T26: 2016 | U26: ASARI | V26: Vision artificielle, trafic & inspection | W26: {=SUMPRODUCT(('📋 Inventaire Complet'!$C$3:$C$517=$V26)*(((COUNTIF($B$6:$B$10,TRUE)=0)+ISNUMBER(IFERROR(MATCH('📋 Inventaire Complet'!$B$3:$B$517,IF($B$6:$B$10,$A$6:$A$10),0),""))>0))*(((COUNTIF($D$6:$D$22,TRUE)=0)+ISNUMBER(IFERROR(MATCH(LEFT('📋 Inventaire Complet'!$J$3:$J$517,4),IF($D$6:$D$22,$C$6:$C$22&""),0),""))>0))*(((COUNTIF($F$6:$F$20,TRUE)=0)+(ISNUMBER(IFERROR(MATCH('📋 Inventaire Complet'!$F$3:$F$517,IF($F$6:$F$19,$E$6:$E$19),0),""))+($F$20*ISNUMBER(MATCH('📋 Inventaire Complet'!$F$3:$F$517,{"D4R";"CEPH";"ISTI";"COLCOM";"HTMR"},0))))>0))*(LEN('📋 Inventaire Complet'!$D$3:$D$517)>0)*(((COUNTIF($H$6:$H$10,TRUE)=0)+(($H$6*ISNUMBER(SEARCH($G$6,'📋 Inventaire Complet'!$L$3:$L$517)))+($H$7*ISNUMBER(SEARCH($G$7,'📋 Inventaire Complet'!$L$3:$L$517)))+($H$8*ISNUMBER(SEARCH($G$8,'📋 Inventaire Complet'!$L$3:$L$517)))+($H$9*ISNUMBER(SEARCH($G$9,'📋 Inventaire Complet'!$L$3:$L$517)))+($H$10*ISNUMBER(SEARCH($G$10,'📋 Inventaire Complet'!$L$3:$L$517))))>0)))} -> 19 | X26: =W26+ROW()/10000 -> 19.0026 | Y26: LAKSSIR, Ouadi | Z26: {=IF(Y26="",0,SUMPRODUCT(('📋 Inventaire Complet'!$E$3:$E$517=Y26)*((COUNTIF($B$6:$B$10,TRUE)=0)+ISNUMBER(IFERROR(MATCH('📋 Inventaire Complet'!$B$3:$B$517,IF($B$6:$B$10,$A$6:$A$10),0),""))>0)*((COUNTIF($D$6:$D$22,TRUE)=0)+ISNUMBER(IFERROR(MATCH(LEFT('📋 Inventaire Complet'!$J$3:$J$517,4),IF($D$6:$D$22,$C$6:$C$22&""),0),""))>0)*((COUNTIF($F$6:$F$20,TRUE)=0)+(ISNUMBER(IFERROR(MATCH('📋 Inventaire Complet'!$F$3:$F$517,IF($F$6:$F$19,$E$6:$E$19),0),""))+($F$20*ISNUMBER(MATCH('📋 Inventaire Complet'!$F$3:$F$517,{"D4R";"CEPH";"ISTI";"COLCOM";"HTMR"},0))))>0)*((COUNTIF($H$6:$H$10,TRUE)=0)+(($H$6*ISNUMBER(SEARCH($G$6,'📋 Inventaire Complet'!$L$3:$L$517)))+($H$7*ISNUMBER(SEARCH($G$7,'📋 Inventaire Complet'!$L$3:$L$517)))+($H$8*ISNUMBER(SEARCH($G$8,'📋 Inventaire Complet'!$L$3:$L$517)))+($H$9*ISNUMBER(SEARCH($G$9,'📋 Inventaire Complet'!$L$3:$L$517)))+($H$10*ISNUMBER(SEARCH($G$10,'📋 Inventaire Complet'!$L$3:$L$517))))>0)))} -> 1 | AA26: =IF(Y26="",0,Z26+ROW()/10000) -> 1.0026
A27: Total brevets | B27: Maintenus actifs | C27: Délivrés / Actifs | D27: PCT international | E27: OMPIC en cours | F27: Abandonnés | G27: Inventeurs uniques | H27: Hub / Laboratoire impliquées | T27: 2017 | U27: GTI | V27: Électronique embarquée, RFID & IoT | W27: {=SUMPRODUCT(('📋 Inventaire Complet'!$C$3:$C$517=$V27)*(((COUNTIF($B$6:$B$10,TRUE)=0)+ISNUMBER(IFERROR(MATCH('📋 Inventaire Complet'!$B$3:$B$517,IF($B$6:$B$10,$A$6:$A$10),0),""))>0))*(((COUNTIF($D$6:$D$22,TRUE)=0)+ISNUMBER(IFERROR(MATCH(LEFT('📋 Inventaire Complet'!$J$3:$J$517,4),IF($D$6:$D$22,$C$6:$C$22&""),0),""))>0))*(((COUNTIF($F$6:$F$20,TRUE)=0)+(ISNUMBER(IFERROR(MATCH('📋 Inventaire Complet'!$F$3:$F$517,IF($F$6:$F$19,$E$6:$E$19),0),""))+($F$20*ISNUMBER(MATCH('📋 Inventaire Complet'!$F$3:$F$517,{"D4R";"CEPH";"ISTI";"COLCOM";"HTMR"},0))))>0))*(LEN('📋 Inventaire Complet'!$D$3:$D$517)>0)*(((COUNTIF($H$6:$H$10,TRUE)=0)+(($H$6*ISNUMBER(SEARCH($G$6,'📋 Inventaire Complet'!$L$3:$L$517)))+($H$7*ISNUMBER(SEARCH($G$7,'📋 Inventaire Complet'!$L$3:$L$517)))+($H$8*ISNUMBER(SEARCH($G$8,'📋 Inventaire Complet'!$L$3:$L$517)))+($H$9*ISNUMBER(SEARCH($G$9,'📋 Inventaire Complet'!$L$3:$L$517)))+($H$10*ISNUMBER(SEARCH($G$10,'📋 Inventaire Complet'!$L$3:$L$517))))>0)))} -> 10 | X27: =W27+ROW()/10000 -> 10.0027 | Y27: Bouhfid, Qaiss | Z27: {=IF(Y27="",0,SUMPRODUCT(('📋 Inventaire Complet'!$E$3:$E$517=Y27)*((COUNTIF($B$6:$B$10,TRUE)=0)+ISNUMBER(IFERROR(MATCH('📋 Inventaire Complet'!$B$3:$B$517,IF($B$6:$B$10,$A$6:$A$10),0),""))>0)*((COUNTIF($D$6:$D$22,TRUE)=0)+ISNUMBER(IFERROR(MATCH(LEFT('📋 Inventaire Complet'!$J$3:$J$517,4),IF($D$6:$D$22,$C$6:$C$22&""),0),""))>0)*((COUNTIF($F$6:$F$20,TRUE)=0)+(ISNUMBER(IFERROR(MATCH('📋 Inventaire Complet'!$F$3:$F$517,IF($F$6:$F$19,$E$6:$E$19),0),""))+($F$20*ISNUMBER(MATCH('📋 Inventaire Complet'!$F$3:$F$517,{"D4R";"CEPH";"ISTI";"COLCOM";"HTMR"},0))))>0)*((COUNTIF($H$6:$H$10,TRUE)=0)+(($H$6*ISNUMBER(SEARCH($G$6,'📋 Inventaire Complet'!$L$3:$L$517)))+($H$7*ISNUMBER(SEARCH($G$7,'📋 Inventaire Complet'!$L$3:$L$517)))+($H$8*ISNUMBER(SEARCH($G$8,'📋 Inventaire Complet'!$L$3:$L$517)))+($H$9*ISNUMBER(SEARCH($G$9,'📋 Inventaire Complet'!$L$3:$L$517)))+($H$10*ISNUMBER(SEARCH($G$10,'📋 Inventaire Complet'!$L$3:$L$517))))>0)))} -> 1 | AA27: =IF(Y27="",0,Z27+ROW()/10000) -> 1.0027
A28: {=SUMPRODUCT((LEN('📋 Inventaire Complet'!D3:D517)>0)*(((COUNTIF($B$6:$B$10,TRUE)=0)+ISNUMBER(IFERROR(MATCH('📋 Inventaire Complet'!$B$3:$B$517,IF($B$6:$B$10,$A$6:$A$10),0),""))>0))*(((COUNTIF($D$6:$D$22,TRUE)=0)+ISNUMBER(IFERROR(MATCH(LEFT('📋 Inventaire Complet'!$J$3:$J$517,4),IF($D$6:$D$22,$C$6:$C$22&""),0),""))>0))*(((COUNTIF($F$6:$F$20,TRUE)=0)+(ISNUMBER(IFERROR(MATCH('📋 Inventaire Complet'!$F$3:$F$517,IF($F$6:$F$19,$E$6:$E$19),0),""))+($F$20*ISNUMBER(MATCH('📋 Inventaire Complet'!F3:F517,{"D4R";"CEPH";"ISTI";"COLCOM";"HTMR"},0))))>0))*(((COUNTIF($H$6:$H$10,TRUE)=0)+(($H$6*ISNUMBER(SEARCH($G$6,'📋 Inventaire Complet'!$L$3:$L$517)))+($H$7*ISNUMBER(SEARCH($G$7,'📋 Inventaire Complet'!$L$3:$L$517)))+($H$8*ISNUMBER(SEARCH($G$8,'📋 Inventaire Complet'!$L$3:$L$517)))+($H$9*ISNUMBER(SEARCH($G$9,'📋 Inventaire Complet'!$L$3:$L$517)))+($H$10*ISNUMBER(SEARCH($G$10,'📋 Inventaire Complet'!$L$3:$L$517))))>0)))} -> 393 | B28: {=SUMPRODUCT((LEN('📋 Inventaire Complet'!D3:D517)>0)*(ISNUMBER(SEARCH("Maintenu",'📋 Inventaire Complet'!L3:L517)))*(((COUNTIF($B$6:$B$10,TRUE)=0)+ISNUMBER(IFERROR(MATCH('📋 Inventaire Complet'!$B$3:$B$517,IF($B$6:$B$10,$A$6:$A$10),0),""))>0))*(((COUNTIF($D$6:$D$22,TRUE)=0)+ISNUMBER(IFERROR(MATCH(LEFT('📋 Inventaire Complet'!$J$3:$J$517,4),IF($D$6:$D$22,$C$6:$C$22&""),0),""))>0))*(((COUNTIF($F$6:$F$20,TRUE)=0)+(ISNUMBER(IFERROR(MATCH('📋 Inventaire Complet'!$F$3:$F$517,IF($F$6:$F$19,$E$6:$E$19),0),""))+($F$20*ISNUMBER(MATCH('📋 Inventaire Complet'!F3:F517,{"D4R";"CEPH";"ISTI";"COLCOM";"HTMR"},0))))>0))*(((COUNTIF($H$6:$H$10,TRUE)=0)+(($H$6*ISNUMBER(SEARCH($G$6,'📋 Inventaire Complet'!$L$3:$L$517)))+($H$7*ISNUMBER(SEARCH($G$7,'📋 Inventaire Complet'!$L$3:$L$517)))+($H$8*ISNUMBER(SEARCH($G$8,'📋 Inventaire Complet'!$L$3:$L$517)))+($H$9*ISNUMBER(SEARCH($G$9,'📋 Inventaire Complet'!$L$3:$L$517)))+($H$10*ISNUMBER(SEARCH($G$10,'📋 Inventaire Complet'!$L$3:$L$517))))>0)))} -> 121 | C28: {=SUMPRODUCT((LEN('📋 Inventaire Complet'!D3:D517)>0)*(ISNUMBER(SEARCH("Délivré",'📋 Inventaire Complet'!L3:L517)))*(((COUNTIF($B$6:$B$10,TRUE)=0)+ISNUMBER(IFERROR(MATCH('📋 Inventaire Complet'!$B$3:$B$517,IF($B$6:$B$10,$A$6:$A$10),0),""))>0))*(((COUNTIF($D$6:$D$22,TRUE)=0)+ISNUMBER(IFERROR(MATCH(LEFT('📋 Inventaire Complet'!$J$3:$J$517,4),IF($D$6:$D$22,$C$6:$C$22&""),0),""))>0))*(((COUNTIF($F$6:$F$20,TRUE)=0)+(ISNUMBER(IFERROR(MATCH('📋 Inventaire Complet'!$F$3:$F$517,IF($F$6:$F$19,$E$6:$E$19),0),""))+($F$20*ISNUMBER(MATCH('📋 Inventaire Complet'!F3:F517,{"D4R";"CEPH";"ISTI";"COLCOM";"HTMR"},0))))>0))*(((COUNTIF($H$6:$H$10,TRUE)=0)+(($H$6*ISNUMBER(SEARCH($G$6,'📋 Inventaire Complet'!$L$3:$L$517)))+($H$7*ISNUMBER(SEARCH($G$7,'📋 Inventaire Complet'!$L$3:$L$517)))+($H$8*ISNUMBER(SEARCH($G$8,'📋 Inventaire Complet'!$L$3:$L$517)))+($H$9*ISNUMBER(SEARCH($G$9,'📋 Inventaire Complet'!$L$3:$L$517)))+($H$10*ISNUMBER(SEARCH($G$10,'📋 Inventaire Complet'!$L$3:$L$517))))>0)))} -> 51 | D28: {=SUMPRODUCT((LEN('📋 Inventaire Complet'!D3:D517)>0)*(ISNUMBER(SEARCH("PCT",'📋 Inventaire Complet'!L3:L517)))*(((COUNTIF($B$6:$B$10,TRUE)=0)+ISNUMBER(IFERROR(MATCH('📋 Inventaire Complet'!$B$3:$B$517,IF($B$6:$B$10,$A$6:$A$10),0),""))>0))*(((COUNTIF($D$6:$D$22,TRUE)=0)+ISNUMBER(IFERROR(MATCH(LEFT('📋 Inventaire Complet'!$J$3:$J$517,4),IF($D$6:$D$22,$C$6:$C$22&""),0),""))>0))*(((COUNTIF($F$6:$F$20,TRUE)=0)+(ISNUMBER(IFERROR(MATCH('📋 Inventaire Complet'!$F$3:$F$517,IF($F$6:$F$19,$E$6:$E$19),0),""))+($F$20*ISNUMBER(MATCH('📋 Inventaire Complet'!F3:F517,{"D4R";"CEPH";"ISTI";"COLCOM";"HTMR"},0))))>0))*(((COUNTIF($H$6:$H$10,TRUE)=0)+(($H$6*ISNUMBER(SEARCH($G$6,'📋 Inventaire Complet'!$L$3:$L$517)))+($H$7*ISNUMBER(SEARCH($G$7,'📋 Inventaire Complet'!$L$3:$L$517)))+($H$8*ISNUMBER(SEARCH($G$8,'📋 Inventaire Complet'!$L$3:$L$517)))+($H$9*ISNUMBER(SEARCH($G$9,'📋 Inventaire Complet'!$L$3:$L$517)))+($H$10*ISNUMBER(SEARCH($G$10,'📋 Inventaire Complet'!$L$3:$L$517))))>0)))} -> 26 | E28: {=SUMPRODUCT((LEN('📋 Inventaire Complet'!D3:D517)>0)*(ISNUMBER(SEARCH("OMPIC",'📋 Inventaire Complet'!L3:L517)))*(((COUNTIF($B$6:$B$10,TRUE)=0)+ISNUMBER(IFERROR(MATCH('📋 Inventaire Complet'!$B$3:$B$517,IF($B$6:$B$10,$A$6:$A$10),0),""))>0))*(((COUNTIF($D$6:$D$22,TRUE)=0)+ISNUMBER(IFERROR(MATCH(LEFT('📋 Inventaire Complet'!$J$3:$J$517,4),IF($D$6:$D$22,$C$6:$C$22&""),0),""))>0))*(((COUNTIF($F$6:$F$20,TRUE)=0)+(ISNUMBER(IFERROR(MATCH('📋 Inventaire Complet'!$F$3:$F$517,IF($F$6:$F$19,$E$6:$E$19),0),""))+($F$20*ISNUMBER(MATCH('📋 Inventaire Complet'!F3:F517,{"D4R";"CEPH";"ISTI";"COLCOM";"HTMR"},0))))>0))*(((COUNTIF($H$6:$H$10,TRUE)=0)+(($H$6*ISNUMBER(SEARCH($G$6,'📋 Inventaire Complet'!$L$3:$L$517)))+($H$7*ISNUMBER(SEARCH($G$7,'📋 Inventaire Complet'!$L$3:$L$517)))+($H$8*ISNUMBER(SEARCH($G$8,'📋 Inventaire Complet'!$L$3:$L$517)))+($H$9*ISNUMBER(SEARCH($G$9,'📋 Inventaire Complet'!$L$3:$L$517)))+($H$10*ISNUMBER(SEARCH($G$10,'📋 Inventaire Complet'!$L$3:$L$517))))>0)))} -> 56 | F28: {=SUMPRODUCT((LEN('📋 Inventaire Complet'!D3:D517)>0)*(ISNUMBER(SEARCH("Abandonné",'📋 Inventaire Complet'!L3:L517)))*(((COUNTIF($B$6:$B$10,TRUE)=0)+ISNUMBER(IFERROR(MATCH('📋 Inventaire Complet'!$B$3:$B$517,IF($B$6:$B$10,$A$6:$A$10),0),""))>0))*(((COUNTIF($D$6:$D$22,TRUE)=0)+ISNUMBER(IFERROR(MATCH(LEFT('📋 Inventaire Complet'!$J$3:$J$517,4),IF($D$6:$D$22,$C$6:$C$22&""),0),""))>0))*(((COUNTIF($F$6:$F$20,TRUE)=0)+(ISNUMBER(IFERROR(MATCH('📋 Inventaire Complet'!$F$3:$F$517,IF($F$6:$F$19,$E$6:$E$19),0),""))+($F$20*ISNUMBER(MATCH('📋 Inventaire Complet'!F3:F517,{"D4R";"CEPH";"ISTI";"COLCOM";"HTMR"},0))))>0))*(((COUNTIF($H$6:$H$10,TRUE)=0)+(($H$6*ISNUMBER(SEARCH($G$6,'📋 Inventaire Complet'!$L$3:$L$517)))+($H$7*ISNUMBER(SEARCH($G$7,'📋 Inventaire Complet'!$L$3:$L$517)))+($H$8*ISNUMBER(SEARCH($G$8,'📋 Inventaire Complet'!$L$3:$L$517)))+($H$9*ISNUMBER(SEARCH($G$9,'📋 Inventaire Complet'!$L$3:$L$517)))+($H$10*ISNUMBER(SEARCH($G$10,'📋 Inventaire Complet'!$L$3:$L$517))))>0)))} -> 44 | G28: {=SUMPRODUCT((LEN('📋 Inventaire Complet'!E3:E517)>0)*(LEN('📋 Inventaire Complet'!D3:D517)>0)*(((COUNTIF($B$6:$B$10,TRUE)=0)+ISNUMBER(IFERROR(MATCH('📋 Inventaire Complet'!$B$3:$B$517,IF($B$6:$B$10,$A$6:$A$10),0),""))>0))*(((COUNTIF($D$6:$D$22,TRUE)=0)+ISNUMBER(IFERROR(MATCH(LEFT('📋 Inventaire Complet'!$J$3:$J$517,4),IF($D$6:$D$22,$C$6:$C$22&""),0),""))>0))*(((COUNTIF($F$6:$F$20,TRUE)=0)+(ISNUMBER(IFERROR(MATCH('📋 Inventaire Complet'!$F$3:$F$517,IF($F$6:$F$19,$E$6:$E$19),0),""))+($F$20*ISNUMBER(MATCH('📋 Inventaire Complet'!F3:F517,{"D4R";"CEPH";"ISTI";"COLCOM";"HTMR"},0))))>0)))} -> 192 | H28: {=SUMPRODUCT(IFERROR((MATCH('📋 Inventaire Complet'!F3:F517,'📋 Inventaire Complet'!F3:F517,0)=ROW('📋 Inventaire Complet'!F3:F517)-2)*(LEN('📋 Inventaire Complet'!F3:F517)>0)*(((COUNTIF($B$6:$B$10,TRUE)=0)+ISNUMBER(IFERROR(MATCH('📋 Inventaire Complet'!$B$3:$B$517,IF($B$6:$B$10,$A$6:$A$10),0),""))>0))*(((COUNTIF($F$6:$F$20,TRUE)=0)+(ISNUMBER(IFERROR(MATCH('📋 Inventaire Complet'!$F$3:$F$517,IF($F$6:$F$19,$E$6:$E$19),0),""))+($F$20*ISNUMBER(MATCH('📋 Inventaire Complet'!F3:F517,{"D4R";"CEPH";"ISTI";"COLCOM";"HTMR"},0))))>0)),0)*(LEN('📋 Inventaire Complet'!$D$3:$D$517)>0))} -> 19 | T28: 2018 | U28: GSMI | V28: Énergie, solaire & efficacité énergétique | W28: {=SUMPRODUCT(('📋 Inventaire Complet'!$C$3:$C$517=$V28)*(((COUNTIF($B$6:$B$10,TRUE)=0)+ISNUMBER(IFERROR(MATCH('📋 Inventaire Complet'!$B$3:$B$517,IF($B$6:$B$10,$A$6:$A$10),0),""))>0))*(((COUNTIF($D$6:$D$22,TRUE)=0)+ISNUMBER(IFERROR(MATCH(LEFT('📋 Inventaire Complet'!$J$3:$J$517,4),IF($D$6:$D$22,$C$6:$C$22&""),0),""))>0))*(((COUNTIF($F$6:$F$20,TRUE)=0)+(ISNUMBER(IFERROR(MATCH('📋 Inventaire Complet'!$F$3:$F$517,IF($F$6:$F$19,$E$6:$E$19),0),""))+($F$20*ISNUMBER(MATCH('📋 Inventaire Complet'!$F$3:$F$517,{"D4R";"CEPH";"ISTI";"COLCOM";"HTMR"},0))))>0))*(LEN('📋 Inventaire Complet'!$D$3:$D$517)>0)*(((COUNTIF($H$6:$H$10,TRUE)=0)+(($H$6*ISNUMBER(SEARCH($G$6,'📋 Inventaire Complet'!$L$3:$L$517)))+($H$7*ISNUMBER(SEARCH($G$7,'📋 Inventaire Complet'!$L$3:$L$517)))+($H$8*ISNUMBER(SEARCH($G$8,'📋 Inventaire Complet'!$L$3:$L$517)))+($H$9*ISNUMBER(SEARCH($G$9,'📋 Inventaire Complet'!$L$3:$L$517)))+($H$10*ISNUMBER(SEARCH($G$10,'📋 Inventaire Complet'!$L$3:$L$517))))>0)))} -> 3 | X28: =W28+ROW()/10000 -> 3.0028 | Y28: qaiss, Bouhfid | Z28: {=IF(Y28="",0,SUMPRODUCT(('📋 Inventaire Complet'!$E$3:$E$517=Y28)*((COUNTIF($B$6:$B$10,TRUE)=0)+ISNUMBER(IFERROR(MATCH('📋 Inventaire Complet'!$B$3:$B$517,IF($B$6:$B$10,$A$6:$A$10),0),""))>0)*((COUNTIF($D$6:$D$22,TRUE)=0)+ISNUMBER(IFERROR(MATCH(LEFT('📋 Inventaire Complet'!$J$3:$J$517,4),IF($D$6:$D$22,$C$6:$C$22&""),0),""))>0)*((COUNTIF($F$6:$F$20,TRUE)=0)+(ISNUMBER(IFERROR(MATCH('📋 Inventaire Complet'!$F$3:$F$517,IF($F$6:$F$19,$E$6:$E$19),0),""))+($F$20*ISNUMBER(MATCH('📋 Inventaire Complet'!$F$3:$F$517,{"D4R";"CEPH";"ISTI";"COLCOM";"HTMR"},0))))>0)*((COUNTIF($H$6:$H$10,TRUE)=0)+(($H$6*ISNUMBER(SEARCH($G$6,'📋 Inventaire Complet'!$L$3:$L$517)))+($H$7*ISNUMBER(SEARCH($G$7,'📋 Inventaire Complet'!$L$3:$L$517)))+($H$8*ISNUMBER(SEARCH($G$8,'📋 Inventaire Complet'!$L$3:$L$517)))+($H$9*ISNUMBER(SEARCH($G$9,'📋 Inventaire Complet'!$L$3:$L$517)))+($H$10*ISNUMBER(SEARCH($G$10,'📋 Inventaire Complet'!$L$3:$L$517))))>0)))} -> 2 | AA28: =IF(Y28="",0,Z28+ROW()/10000) -> 2.0028
T29: 2019 | U29: LIMSET | V29: Ferrites, nanomatériaux magnétiques & magnétocaloriques | W29: {=SUMPRODUCT(('📋 Inventaire Complet'!$C$3:$C$517=$V29)*(((COUNTIF($B$6:$B$10,TRUE)=0)+ISNUMBER(IFERROR(MATCH('📋 Inventaire Complet'!$B$3:$B$517,IF($B$6:$B$10,$A$6:$A$10),0),""))>0))*(((COUNTIF($D$6:$D$22,TRUE)=0)+ISNUMBER(IFERROR(MATCH(LEFT('📋 Inventaire Complet'!$J$3:$J$517,4),IF($D$6:$D$22,$C$6:$C$22&""),0),""))>0))*(((COUNTIF($F$6:$F$20,TRUE)=0)+(ISNUMBER(IFERROR(MATCH('📋 Inventaire Complet'!$F$3:$F$517,IF($F$6:$F$19,$E$6:$E$19),0),""))+($F$20*ISNUMBER(MATCH('📋 Inventaire Complet'!$F$3:$F$517,{"D4R";"CEPH";"ISTI";"COLCOM";"HTMR"},0))))>0))*(LEN('📋 Inventaire Complet'!$D$3:$D$517)>0)*(((COUNTIF($H$6:$H$10,TRUE)=0)+(($H$6*ISNUMBER(SEARCH($G$6,'📋 Inventaire Complet'!$L$3:$L$517)))+($H$7*ISNUMBER(SEARCH($G$7,'📋 Inventaire Complet'!$L$3:$L$517)))+($H$8*ISNUMBER(SEARCH($G$8,'📋 Inventaire Complet'!$L$3:$L$517)))+($H$9*ISNUMBER(SEARCH($G$9,'📋 Inventaire Complet'!$L$3:$L$517)))+($H$10*ISNUMBER(SEARCH($G$10,'📋 Inventaire Complet'!$L$3:$L$517))))>0)))} -> 18 | X29: =W29+ROW()/10000 -> 18.0029 | Y29: ABOU EL KACEM QAISS BOUHFID RACHID ESSABIR HAMID | Z29: {=IF(Y29="",0,SUMPRODUCT(('📋 Inventaire Complet'!$E$3:$E$517=Y29)*((COUNTIF($B$6:$B$10,TRUE)=0)+ISNUMBER(IFERROR(MATCH('📋 Inventaire Complet'!$B$3:$B$517,IF($B$6:$B$10,$A$6:$A$10),0),""))>0)*((COUNTIF($D$6:$D$22,TRUE)=0)+ISNUMBER(IFERROR(MATCH(LEFT('📋 Inventaire Complet'!$J$3:$J$517,4),IF($D$6:$D$22,$C$6:$C$22&""),0),""))>0)*((COUNTIF($F$6:$F$20,TRUE)=0)+(ISNUMBER(IFERROR(MATCH('📋 Inventaire Complet'!$F$3:$F$517,IF($F$6:$F$19,$E$6:$E$19),0),""))+($F$20*ISNUMBER(MATCH('📋 Inventaire Complet'!$F$3:$F$517,{"D4R";"CEPH";"ISTI";"COLCOM";"HTMR"},0))))>0)*((COUNTIF($H$6:$H$10,TRUE)=0)+(($H$6*ISNUMBER(SEARCH($G$6,'📋 Inventaire Complet'!$L$3:$L$517)))+($H$7*ISNUMBER(SEARCH($G$7,'📋 Inventaire Complet'!$L$3:$L$517)))+($H$8*ISNUMBER(SEARCH($G$8,'📋 Inventaire Complet'!$L$3:$L$517)))+($H$9*ISNUMBER(SEARCH($G$9,'📋 Inventaire Complet'!$L$3:$L$517)))+($H$10*ISNUMBER(SEARCH($G$10,'📋 Inventaire Complet'!$L$3:$L$517))))>0)))} -> 1 | AA29: =IF(Y29="",0,Z29+ROW()/10000) -> 1.0029
A30: 5 dernières années | B30: Moyenne /an | C30: Année record | D30: Dernier dépôt | E30: % Délivré + Maint. | F30: % Abandonné | G30: % Inv. renseigné | H30: % Couv. géo. | T30: 2020 | U30: DICE | V30: Fertilisants phosphatés & sels de phosphate | W30: {=SUMPRODUCT(('📋 Inventaire Complet'!$C$3:$C$517=$V30)*(((COUNTIF($B$6:$B$10,TRUE)=0)+ISNUMBER(IFERROR(MATCH('📋 Inventaire Complet'!$B$3:$B$517,IF($B$6:$B$10,$A$6:$A$10),0),""))>0))*(((COUNTIF($D$6:$D$22,TRUE)=0)+ISNUMBER(IFERROR(MATCH(LEFT('📋 Inventaire Complet'!$J$3:$J$517,4),IF($D$6:$D$22,$C$6:$C$22&""),0),""))>0))*(((COUNTIF($F$6:$F$20,TRUE)=0)+(ISNUMBER(IFERROR(MATCH('📋 Inventaire Complet'!$F$3:$F$517,IF($F$6:$F$19,$E$6:$E$19),0),""))+($F$20*ISNUMBER(MATCH('📋 Inventaire Complet'!$F$3:$F$517,{"D4R";"CEPH";"ISTI";"COLCOM";"HTMR"},0))))>0))*(LEN('📋 Inventaire Complet'!$D$3:$D$517)>0)*(((COUNTIF($H$6:$H$10,TRUE)=0)+(($H$6*ISNUMBER(SEARCH($G$6,'📋 Inventaire Complet'!$L$3:$L$517)))+($H$7*ISNUMBER(SEARCH($G$7,'📋 Inventaire Complet'!$L$3:$L$517)))+($H$8*ISNUMBER(SEARCH($G$8,'📋 Inventaire Complet'!$L$3:$L$517)))+($H$9*ISNUMBER(SEARCH($G$9,'📋 Inventaire Complet'!$L$3:$L$517)))+($H$10*ISNUMBER(SEARCH($G$10,'📋 Inventaire Complet'!$L$3:$L$517))))>0)))} -> 17 | X30: =W30+ROW()/10000 -> 17.003 | Y30: QAISS, BOUHFID | Z30: {=IF(Y30="",0,SUMPRODUCT(('📋 Inventaire Complet'!$E$3:$E$517=Y30)*((COUNTIF($B$6:$B$10,TRUE)=0)+ISNUMBER(IFERROR(MATCH('📋 Inventaire Complet'!$B$3:$B$517,IF($B$6:$B$10,$A$6:$A$10),0),""))>0)*((COUNTIF($D$6:$D$22,TRUE)=0)+ISNUMBER(IFERROR(MATCH(LEFT('📋 Inventaire Complet'!$J$3:$J$517,4),IF($D$6:$D$22,$C$6:$C$22&""),0),""))>0)*((COUNTIF($F$6:$F$20,TRUE)=0)+(ISNUMBER(IFERROR(MATCH('📋 Inventaire Complet'!$F$3:$F$517,IF($F$6:$F$19,$E$6:$E$19),0),""))+($F$20*ISNUMBER(MATCH('📋 Inventaire Complet'!$F$3:$F$517,{"D4R";"CEPH";"ISTI";"COLCOM";"HTMR"},0))))>0)*((COUNTIF($H$6:$H$10,TRUE)=0)+(($H$6*ISNUMBER(SEARCH($G$6,'📋 Inventaire Complet'!$L$3:$L$517)))+($H$7*ISNUMBER(SEARCH($G$7,'📋 Inventaire Complet'!$L$3:$L$517)))+($H$8*ISNUMBER(SEARCH($G$8,'📋 Inventaire Complet'!$L$3:$L$517)))+($H$9*ISNUMBER(SEARCH($G$9,'📋 Inventaire Complet'!$L$3:$L$517)))+($H$10*ISNUMBER(SEARCH($G$10,'📋 Inventaire Complet'!$L$3:$L$517))))>0)))} -> 2 | AA30: =IF(Y30="",0,Z30+ROW()/10000) -> 2.003
A31: {=SUMPRODUCT((LEN('📋 Inventaire Complet'!D3:D517)>0)*(IFERROR(VALUE(LEFT('📋 Inventaire Complet'!J3:J517,4)),0)>=YEAR(TODAY())-5)*(((COUNTIF($B$6:$B$10,TRUE)=0)+ISNUMBER(IFERROR(MATCH('📋 Inventaire Complet'!$B$3:$B$517,IF($B$6:$B$10,$A$6:$A$10),0),""))>0))*(((COUNTIF($F$6:$F$20,TRUE)=0)+(ISNUMBER(IFERROR(MATCH('📋 Inventaire Complet'!$F$3:$F$517,IF($F$6:$F$19,$E$6:$E$19),0),""))+($F$20*ISNUMBER(MATCH('📋 Inventaire Complet'!F3:F517,{"D4R";"CEPH";"ISTI";"COLCOM";"HTMR"},0))))>0))*(((COUNTIF($H$6:$H$10,TRUE)=0)+(($H$6*ISNUMBER(SEARCH($G$6,'📋 Inventaire Complet'!$L$3:$L$517)))+($H$7*ISNUMBER(SEARCH($G$7,'📋 Inventaire Complet'!$L$3:$L$517)))+($H$8*ISNUMBER(SEARCH($G$8,'📋 Inventaire Complet'!$L$3:$L$517)))+($H$9*ISNUMBER(SEARCH($G$9,'📋 Inventaire Complet'!$L$3:$L$517)))+($H$10*ISNUMBER(SEARCH($G$10,'📋 Inventaire Complet'!$L$3:$L$517))))>0)))} -> 101 | B31: {=IFERROR(SUMPRODUCT((LEN('📋 Inventaire Complet'!D3:D517)>0)*(IFERROR(VALUE(LEFT('📋 Inventaire Complet'!J3:J517,4)),0)>0)*(((COUNTIF($B$6:$B$10,TRUE)=0)+ISNUMBER(IFERROR(MATCH('📋 Inventaire Complet'!$B$3:$B$517,IF($B$6:$B$10,$A$6:$A$10),0),""))>0))*(((COUNTIF($F$6:$F$20,TRUE)=0)+(ISNUMBER(IFERROR(MATCH('📋 Inventaire Complet'!$F$3:$F$517,IF($F$6:$F$19,$E$6:$E$19),0),""))+($F$20*ISNUMBER(MATCH('📋 Inventaire Complet'!F3:F517,{"D4R";"CEPH";"ISTI";"COLCOM";"HTMR"},0))))>0))*(((COUNTIF($H$6:$H$10,TRUE)=0)+(($H$6*ISNUMBER(SEARCH($G$6,'📋 Inventaire Complet'!$L$3:$L$517)))+($H$7*ISNUMBER(SEARCH($G$7,'📋 Inventaire Complet'!$L$3:$L$517)))+($H$8*ISNUMBER(SEARCH($G$8,'📋 Inventaire Complet'!$L$3:$L$517)))+($H$9*ISNUMBER(SEARCH($G$9,'📋 Inventaire Complet'!$L$3:$L$517)))+($H$10*ISNUMBER(SEARCH($G$10,'📋 Inventaire Complet'!$L$3:$L$517))))>0)))/(MAX(IFERROR(VALUE(LEFT('📋 Inventaire Complet'!J3:J517,4)),0))-MIN(IF(IFERROR(VALUE(LEFT('📋 Inventaire Complet'!J3:J517,4)),0)>0,IFERROR(VALUE(LEFT('📋 Inventaire Complet'!J3:J517,4)),9999)))+1),0)} -> 16.117647 | C31: =IFERROR(INDEX($A$53:$A$69,MATCH(MAX($G$53:$G$69),$G$53:$G$69,0)),"-") -> 2015 | D31: {=MAX(IFERROR(VALUE(LEFT('📋 Inventaire Complet'!J3:J517,4)),0))} -> 2026 | E31: =IFERROR((B28+C28)/A28,0) -> 0.43765903 | F31: =IFERROR(F28/A28,0) -> 0.11195929 | G31: =IFERROR(G28/A28,0) -> 0.48854962 | H31: {=IFERROR(SUMPRODUCT((LEN('📋 Inventaire Complet'!D3:D517)>0)*(LEN('📋 Inventaire Complet'!M3:M517)>0)*(((COUNTIF($B$6:$B$10,TRUE)=0)+ISNUMBER(IFERROR(MATCH('📋 Inventaire Complet'!$B$3:$B$517,IF($B$6:$B$10,$A$6:$A$10),0),""))>0))*(((COUNTIF($D$6:$D$22,TRUE)=0)+ISNUMBER(IFERROR(MATCH(LEFT('📋 Inventaire Complet'!$J$3:$J$517,4),IF($D$6:$D$22,$C$6:$C$22&""),0),""))>0))*(((COUNTIF($F$6:$F$20,TRUE)=0)+(ISNUMBER(IFERROR(MATCH('📋 Inventaire Complet'!$F$3:$F$517,IF($F$6:$F$19,$E$6:$E$19),0),""))+($F$20*ISNUMBER(MATCH('📋 Inventaire Complet'!F3:F517,{"D4R";"CEPH";"ISTI";"COLCOM";"HTMR"},0))))>0)))/A28,0)} -> 0.67684478 | T31: 2021 | U31: TechCell | V31: Flottation & enrichissement des minerais | W31: {=SUMPRODUCT(('📋 Inventaire Complet'!$C$3:$C$517=$V31)*(((COUNTIF($B$6:$B$10,TRUE)=0)+ISNUMBER(IFERROR(MATCH('📋 Inventaire Complet'!$B$3:$B$517,IF($B$6:$B$10,$A$6:$A$10),0),""))>0))*(((COUNTIF($D$6:$D$22,TRUE)=0)+ISNUMBER(IFERROR(MATCH(LEFT('📋 Inventaire Complet'!$J$3:$J$517,4),IF($D$6:$D$22,$C$6:$C$22&""),0),""))>0))*(((COUNTIF($F$6:$F$20,TRUE)=0)+(ISNUMBER(IFERROR(MATCH('📋 Inventaire Complet'!$F$3:$F$517,IF($F$6:$F$19,$E$6:$E$19),0),""))+($F$20*ISNUMBER(MATCH('📋 Inventaire Complet'!$F$3:$F$517,{"D4R";"CEPH";"ISTI";"COLCOM";"HTMR"},0))))>0))*(LEN('📋 Inventaire Complet'!$D$3:$D$517)>0)*(((COUNTIF($H$6:$H$10,TRUE)=0)+(($H$6*ISNUMBER(SEARCH($G$6,'📋 Inventaire Complet'!$L$3:$L$517)))+($H$7*ISNUMBER(SEARCH($G$7,'📋 Inventaire Complet'!$L$3:$L$517)))+($H$8*ISNUMBER(SEARCH($G$8,'📋 Inventaire Complet'!$L$3:$L$517)))+($H$9*ISNUMBER(SEARCH($G$9,'📋 Inventaire Complet'!$L$3:$L$517)))+($H$10*ISNUMBER(SEARCH($G$10,'📋 Inventaire Complet'!$L$3:$L$517))))>0)))} -> 5 | X31: =W31+ROW()/10000 -> 5.0031 | Y31: El Moussaoui Hassan Hamedooune Mohammed Mounkachi Omar benyoussef Abdelilah | Z31: {=IF(Y31="",0,SUMPRODUCT(('📋 Inventaire Complet'!$E$3:$E$517=Y31)*((COUNTIF($B$6:$B$10,TRUE)=0)+ISNUMBER(IFERROR(MATCH('📋 Inventaire Complet'!$B$3:$B$517,IF($B$6:$B$10,$A$6:$A$10),0),""))>0)*((COUNTIF($D$6:$D$22,TRUE)=0)+ISNUMBER(IFERROR(MATCH(LEFT('📋 Inventaire Complet'!$J$3:$J$517,4),IF($D$6:$D$22,$C$6:$C$22&""),0),""))>0)*((COUNTIF($F$6:$F$20,TRUE)=0)+(ISNUMBER(IFERROR(MATCH('📋 Inventaire Complet'!$F$3:$F$517,IF($F$6:$F$19,$E$6:$E$19),0),""))+($F$20*ISNUMBER(MATCH('📋 Inventaire Complet'!$F$3:$F$517,{"D4R";"CEPH";"ISTI";"COLCOM";"HTMR"},0))))>0)*((COUNTIF($H$6:$H$10,TRUE)=0)+(($H$6*ISNUMBER(SEARCH($G$6,'📋 Inventaire Complet'!$L$3:$L$517)))+($H$7*ISNUMBER(SEARCH($G$7,'📋 Inventaire Complet'!$L$3:$L$517)))+($H$8*ISNUMBER(SEARCH($G$8,'📋 Inventaire Complet'!$L$3:$L$517)))+($H$9*ISNUMBER(SEARCH($G$9,'📋 Inventaire Complet'!$L$3:$L$517)))+($H$10*ISNUMBER(SEARCH($G$10,'📋 Inventaire Complet'!$L$3:$L$517))))>0)))} -> 1 | AA31: =IF(Y31="",0,Z31+ROW()/10000) -> 1.0031
T32: 2022 | U32: ILO | V32: Matériaux composites, verre & catalyseurs | W32: {=SUMPRODUCT(('📋 Inventaire Complet'!$C$3:$C$517=$V32)*(((COUNTIF($B$6:$B$10,TRUE)=0)+ISNUMBER(IFERROR(MATCH('📋 Inventaire Complet'!$B$3:$B$517,IF($B$6:$B$10,$A$6:$A$10),0),""))>0))*(((COUNTIF($D$6:$D$22,TRUE)=0)+ISNUMBER(IFERROR(MATCH(LEFT('📋 Inventaire Complet'!$J$3:$J$517,4),IF($D$6:$D$22,$C$6:$C$22&""),0),""))>0))*(((COUNTIF($F$6:$F$20,TRUE)=0)+(ISNUMBER(IFERROR(MATCH('📋 Inventaire Complet'!$F$3:$F$517,IF($F$6:$F$19,$E$6:$E$19),0),""))+($F$20*ISNUMBER(MATCH('📋 Inventaire Complet'!$F$3:$F$517,{"D4R";"CEPH";"ISTI";"COLCOM";"HTMR"},0))))>0))*(LEN('📋 Inventaire Complet'!$D$3:$D$517)>0)*(((COUNTIF($H$6:$H$10,TRUE)=0)+(($H$6*ISNUMBER(SEARCH($G$6,'📋 Inventaire Complet'!$L$3:$L$517)))+($H$7*ISNUMBER(SEARCH($G$7,'📋 Inventaire Complet'!$L$3:$L$517)))+($H$8*ISNUMBER(SEARCH($G$8,'📋 Inventaire Complet'!$L$3:$L$517)))+($H$9*ISNUMBER(SEARCH($G$9,'📋 Inventaire Complet'!$L$3:$L$517)))+($H$10*ISNUMBER(SEARCH($G$10,'📋 Inventaire Complet'!$L$3:$L$517))))>0)))} -> 12 | X32: =W32+ROW()/10000 -> 12.0032 | Y32: RAJI MARYA; QAISS ABOU EL KACEM; BOUHFID RACHID | Z32: {=IF(Y32="",0,SUMPRODUCT(('📋 Inventaire Complet'!$E$3:$E$517=Y32)*((COUNTIF($B$6:$B$10,TRUE)=0)+ISNUMBER(IFERROR(MATCH('📋 Inventaire Complet'!$B$3:$B$517,IF($B$6:$B$10,$A$6:$A$10),0),""))>0)*((COUNTIF($D$6:$D$22,TRUE)=0)+ISNUMBER(IFERROR(MATCH(LEFT('📋 Inventaire Complet'!$J$3:$J$517,4),IF($D$6:$D$22,$C$6:$C$22&""),0),""))>0)*((COUNTIF($F$6:$F$20,TRUE)=0)+(ISNUMBER(IFERROR(MATCH('📋 Inventaire Complet'!$F$3:$F$517,IF($F$6:$F$19,$E$6:$E$19),0),""))+($F$20*ISNUMBER(MATCH('📋 Inventaire Complet'!$F$3:$F$517,{"D4R";"CEPH";"ISTI";"COLCOM";"HTMR"},0))))>0)*((COUNTIF($H$6:$H$10,TRUE)=0)+(($H$6*ISNUMBER(SEARCH($G$6,'📋 Inventaire Complet'!$L$3:$L$517)))+($H$7*ISNUMBER(SEARCH($G$7,'📋 Inventaire Complet'!$L$3:$L$517)))+($H$8*ISNUMBER(SEARCH($G$8,'📋 Inventaire Complet'!$L$3:$L$517)))+($H$9*ISNUMBER(SEARCH($G$9,'📋 Inventaire Complet'!$L$3:$L$517)))+($H$10*ISNUMBER(SEARCH($G$10,'📋 Inventaire Complet'!$L$3:$L$517))))>0)))} -> 1 | AA32: =IF(Y32="",0,Z32+ROW()/10000) -> 1.0032
A33: RÉPARTITION PAR THÉMATIQUE | E33: RÉPARTITION PAR HUB/LABORATOIRE | I33: RÉPARTITION PAR STATUT | T33: 2023 | U33: Al-Moutmir | V33: Phosphogypse, gypse & co-produits | W33: {=SUMPRODUCT(('📋 Inventaire Complet'!$C$3:$C$517=$V33)*(((COUNTIF($B$6:$B$10,TRUE)=0)+ISNUMBER(IFERROR(MATCH('📋 Inventaire Complet'!$B$3:$B$517,IF($B$6:$B$10,$A$6:$A$10),0),""))>0))*(((COUNTIF($D$6:$D$22,TRUE)=0)+ISNUMBER(IFERROR(MATCH(LEFT('📋 Inventaire Complet'!$J$3:$J$517,4),IF($D$6:$D$22,$C$6:$C$22&""),0),""))>0))*(((COUNTIF($F$6:$F$20,TRUE)=0)+(ISNUMBER(IFERROR(MATCH('📋 Inventaire Complet'!$F$3:$F$517,IF($F$6:$F$19,$E$6:$E$19),0),""))+($F$20*ISNUMBER(MATCH('📋 Inventaire Complet'!$F$3:$F$517,{"D4R";"CEPH";"ISTI";"COLCOM";"HTMR"},0))))>0))*(LEN('📋 Inventaire Complet'!$D$3:$D$517)>0)*(((COUNTIF($H$6:$H$10,TRUE)=0)+(($H$6*ISNUMBER(SEARCH($G$6,'📋 Inventaire Complet'!$L$3:$L$517)))+($H$7*ISNUMBER(SEARCH($G$7,'📋 Inventaire Complet'!$L$3:$L$517)))+($H$8*ISNUMBER(SEARCH($G$8,'📋 Inventaire Complet'!$L$3:$L$517)))+($H$9*ISNUMBER(SEARCH($G$9,'📋 Inventaire Complet'!$L$3:$L$517)))+($H$10*ISNUMBER(SEARCH($G$10,'📋 Inventaire Complet'!$L$3:$L$517))))>0)))} -> 3 | X33: =W33+ROW()/10000 -> 3.0033 | Y33: BOUHFID Rachid ABOU EL KACEM Qaiss | Z33: {=IF(Y33="",0,SUMPRODUCT(('📋 Inventaire Complet'!$E$3:$E$517=Y33)*((COUNTIF($B$6:$B$10,TRUE)=0)+ISNUMBER(IFERROR(MATCH('📋 Inventaire Complet'!$B$3:$B$517,IF($B$6:$B$10,$A$6:$A$10),0),""))>0)*((COUNTIF($D$6:$D$22,TRUE)=0)+ISNUMBER(IFERROR(MATCH(LEFT('📋 Inventaire Complet'!$J$3:$J$517,4),IF($D$6:$D$22,$C$6:$C$22&""),0),""))>0)*((COUNTIF($F$6:$F$20,TRUE)=0)+(ISNUMBER(IFERROR(MATCH('📋 Inventaire Complet'!$F$3:$F$517,IF($F$6:$F$19,$E$6:$E$19),0),""))+($F$20*ISNUMBER(MATCH('📋 Inventaire Complet'!$F$3:$F$517,{"D4R";"CEPH";"ISTI";"COLCOM";"HTMR"},0))))>0)*((COUNTIF($H$6:$H$10,TRUE)=0)+(($H$6*ISNUMBER(SEARCH($G$6,'📋 Inventaire Complet'!$L$3:$L$517)))+($H$7*ISNUMBER(SEARCH($G$7,'📋 Inventaire Complet'!$L$3:$L$517)))+($H$8*ISNUMBER(SEARCH($G$8,'📋 Inventaire Complet'!$L$3:$L$517)))+($H$9*ISNUMBER(SEARCH($G$9,'📋 Inventaire Complet'!$L$3:$L$517)))+($H$10*ISNUMBER(SEARCH($G$10,'📋 Inventaire Complet'!$L$3:$L$517))))>0)))} -> 1 | AA33: =IF(Y33="",0,Z33+ROW()/10000) -> 1.0033
